<?xml version="1.0" ?>
<sdf version='1.4'>
  <model name='robot_hand'>
    <link name='base_link'>
      <pose>0 0 0 0 -0 0</pose>
      <inertial>
        <pose>0.000759234 4.26041e-19 0.0404474 0 -0 0</pose>
        <mass>0.0629149</mass>
        <inertia>
          <ixx>7.11135e-05</ixx>
          <ixy>1.03996e-21</ixy>
          <ixz>1.97005e-06</ixz>
          <iyy>0.00010929</iyy>
          <iyz>-2.50104e-22</iyz>
          <izz>4.5574e-05</izz>
        </inertia>
      </inertial>
      <collision name='base_link_collision'>
        <pose>0 0 0 0 -0 0</pose>
        <geometry>
          <mesh>
            <scale>10 10 10</scale>
            <uri>model://robot_hand/meshes/base_link.STL</uri>
          </mesh>
        </geometry>
      </collision>
      <visual name='base_link_visual'>
        <pose>0 0 0 0 -0 0</pose>
        <geometry>
          <mesh>
            <scale>10 10 10</scale>
            <uri>model://robot_hand/meshes/base_link.dae</uri>
          </mesh>
        </geometry>
      </visual>
      <velocity_decay>
        <linear>0</linear>
        <angular>0</angular>
      </velocity_decay>
    </link>
    <link name='finger_1'>
      <pose>0.234 0.01 0 1.5708 -0.017453 -1.5708</pose>
      <inertial>
        <pose>-0.038749 -0.018152 -0.011 0 -0 0</pose>
        <mass>0.023536</mass>
        <inertia>
          <ixx>1.2095e-05</ixx>
          <ixy>5.7044e-06</ixy>
          <ixz>-4.6491e-16</ixz>
          <iyy>8.8391e-06</iyy>
          <iyz>3.4685e-16</iyz>
          <izz>1.8544e-05</izz>
        </inertia>
      </inertial>
      <collision name='finger_1_collision'>
        <pose>0 0 0 0 -0 0</pose>
        <geometry>
          <mesh>
            <scale>10 10 10</scale>
            <uri>model://robot_hand/meshes/finger_1.STL</uri>
          </mesh>
        </geometry>
      </collision>
      <visual name='finger_1_visual'>
        <pose>0 0 0 0 -0 0</pose>
        <geometry>
          <mesh>
            <scale>10 10 10</scale>
            <uri>model://robot_hand/meshes/finger_1.dae</uri>
          </mesh>
        </geometry>
      </visual>
      <velocity_decay>
        <linear>0</linear>
        <angular>0</angular>
      </velocity_decay>
    </link>
    <joint name='joint_1' type='revolute'>
      <child>finger_1</child>
      <parent>base_link</parent>
      <axis>
        <xyz>-1 3.6091e-06 -3.67265e-06</xyz>
        <limit>
          <lower>-0.6</lower>
          <upper>1.3788</upper>
          <effort>0</effort>
          <velocity>0</velocity>
        </limit>
        <dynamics/>
      </axis>
    </joint>
    <link name='finger_2'>
      <pose>0 0.01 0 1.5708 -0.52049 -1.5708</pose>
      <inertial>
        <pose>-0.054048 -0.00040729 4.8547e-13 0 -0 0</pose>
        <mass>0.023536</mass>
        <inertia>
          <ixx>2.0487e-06</ixx>
          <ixy>3.3905e-07</ixy>
          <ixz>1.6633e-16</ixz>
          <iyy>2.5629e-05</iyy>
          <iyz>7.6674e-18</iyz>
          <izz>2.5288e-05</izz>
        </inertia>
      </inertial>
      <collision name='finger_2_collision'>
        <pose>0 0 0 0 -0 0</pose>
        <geometry>
          <mesh>
            <scale>10 10 10</scale>
            <uri>model://robot_hand/meshes/finger_2.STL</uri>
          </mesh>
        </geometry>
      </collision>
      <visual name='finger_2_visual'>
        <pose>0 0 0 0 -0 0</pose>
        <geometry>
          <mesh>
            <scale>10 10 10</scale>
            <uri>model://robot_hand/meshes/finger_2.dae</uri>
          </mesh>
        </geometry>
      </visual>
      <velocity_decay>
        <linear>0</linear>
        <angular>0</angular>
      </velocity_decay>
    </link>
    <joint name='joint_2' type='revolute'>
      <child>finger_2</child>
      <parent>base_link</parent>
      <axis>
        <xyz>-1 1.8465e-06 -3.18678e-06</xyz>
        <limit>
          <lower>-0.50304</lower>
          <upper>0.87577</upper>
          <effort>0</effort>
          <velocity>0</velocity>
        </limit>
        <dynamics/>
      </axis>
    </joint>
    <link name='finger_3'>
      <pose>-0.234 0.01 0 1.5708 -0.52705 -1.5708</pose>
      <inertial>
        <pose>-0.052747 -0.0035714 0.011 0 -0 0</pose>
        <mass>0.023536</mass>
        <inertia>
          <ixx>3.0246e-06</ixx>
          <ixy>3.2002e-06</ixy>
          <ixz>-1.0623e-14</ixz>
          <iyy>2.3113e-05</iyy>
          <iyz>-1.1386e-15</iyz>
          <izz>2.3748e-05</izz>
        </inertia>
      </inertial>
      <collision name='finger_3_collision'>
        <pose>0 0 0 0 -0 0</pose>
        <geometry>
          <mesh>
            <scale>10 10 10</scale>
            <uri>model://robot_hand/meshes/finger_3.STL</uri>
          </mesh>
        </geometry>
      </collision>
      <visual name='finger_3_visual'>
        <pose>0 0 0 0 -0 0</pose>
        <geometry>
          <mesh>
            <scale>10 10 10</scale>
            <uri>model://robot_hand/meshes/finger_3.dae</uri>
          </mesh>
        </geometry>
      </visual>
      <velocity_decay>
        <linear>0</linear>
        <angular>0</angular>
      </velocity_decay>
    </link>
    <joint name='joint_3' type='revolute'>
      <child>finger_3</child>
      <parent>base_link</parent>
      <axis>
        <xyz>-1 1.82563e-06 -3.17473e-06</xyz>
        <limit>
          <lower>-0.50959</lower>
          <upper>0.86922</upper>
          <effort>0</effort>
          <velocity>0</velocity>
        </limit>
        <dynamics/>
      </axis>
    </joint>
     <joint name = "my_mass_joint" type="prismatic">
        <parent>world</parent>
          <child>base_link</child>
          <axis>
            <xyz>0 0 1</xyz>
          </axis>
      </joint>
      <plugin name="mass_joint" filename="libMassJoint.so" />

  </model>
</sdf>
