<sdf version='1.4'>
  <model name='spring_board'>
    <pose>0 0 0.5 0 -0 0</pose>
    <link name='plane'>
      <pose>0 0 0.1 0 -0 0</pose>
      <inertial>
        <mass>20</mass>
      </inertial>
      <collision name='collision'>
        <geometry>
          <box>
            <size>4 4 0.2</size>
          </box>
        </geometry>
        <surface>
          <friction>
            <ode>
              <mu>0</mu>
              <mu2>0</mu2>
            </ode>
          </friction>
        </surface>
      </collision>
      <visual name='visual'>
        <geometry>
          <box>
            <size>4 4 0.2</size>
          </box>
        </geometry>
        <material>
          <ambient>1 1 1 1</ambient>
          <diffuse>1 1 1 1</diffuse>
          <specular>0.1 0.1 0.1 1</specular>
          <emissive>0 0 0 0</emissive>
        </material>
      </visual>
      <velocity_decay>
        <linear>0</linear>
        <angular>0</angular>
      </velocity_decay>
    </link>
    <joint name='plane_joint' type='prismatic'>
      <parent>world</parent>
      <child>plane</child>
      <axis>
        <xyz>0 0 1</xyz>
        <limit>
          <lower>-1e+16</lower>
          <upper>1e+16</upper>
        </limit>
      </axis>
    </joint>
    <link name='spring_1'>
      <pose>-1.5 1.5 1.3 0 -0 0</pose>
      <inertial>
        <mass>0.001</mass>
      </inertial>
      <collision name='sphere_collision'>
        <geometry>
          <sphere>
            <radius>0.25</radius>
          </sphere>
        </geometry>
        <surface>
          <friction>
            <ode>
              <mu>0</mu>
              <mu2>0</mu2>
            </ode>
          </friction>
        </surface>
      </collision>
      <visual name='visual'>
        <geometry>
          <sphere>
            <radius>0.25</radius>
          </sphere>
        </geometry>
        <material>
          <ambient>1 1 1 1</ambient>
          <diffuse>1 1 1 1</diffuse>
          <specular>0.1 0.1 0.1 1</specular>
          <emissive>0 0 0 0</emissive>
        </material>
      </visual>
      <velocity_decay>
        <linear>0</linear>
        <angular>0</angular>
      </velocity_decay>
    </link>
    <joint name='spring_joint_1' type='prismatic'>
      <parent>tactile_1</parent>
      <child>spring_1</child>
      <axis>
        <xyz>0 0 1</xyz>
        <limit>
          <lower>-1e+16</lower>
          <upper>1e+16</upper>
        </limit>
      </axis>
    </joint>
    <link name='tactile_1'>
      <pose>-1.5 1.5 0.4 0 -0 0</pose>
      <inertial>
        <mass>0.001</mass>
      </inertial>
      <collision name='square_collision'>
        <geometry>
          <box>
            <size>0.5 0.5 0.01</size>
          </box>
        </geometry>
        <surface>
          <friction>
            <ode>
              <mu>0</mu>
              <mu2>0</mu2>
            </ode>
          </friction>
        </surface>
      </collision>
      <visual name='visual'>
        <geometry>
          <box>
            <size>0.5 0.5 0.01</size>
          </box>
        </geometry>
        <material>
          <ambient>1 0 0 1</ambient>
          <diffuse>1 0 0 1</diffuse>
          <specular>0.1 0.1 0.1 1</specular>
          <emissive>0 0 0 0</emissive>
        </material>
      </visual>
      <velocity_decay>
        <linear>0</linear>
        <angular>0</angular>
      </velocity_decay>
    </link>
    <joint name='tactile_joint_1' type='prismatic'>
      <parent>plane</parent>
      <child>tactile_1</child>
      <axis>
        <xyz>0 0 1</xyz>
        <limit>
          <lower>-1e+16</lower>
          <upper>1e+16</upper>
        </limit>
      </axis>
    </joint>
    <link name='spring_2'>
      <pose>-1 1.5 1.3 0 -0 0</pose>
      <inertial>
        <mass>0.001</mass>
      </inertial>
      <collision name='sphere_collision'>
        <geometry>
          <sphere>
            <radius>0.25</radius>
          </sphere>
        </geometry>
        <surface>
          <friction>
            <ode>
              <mu>0</mu>
              <mu2>0</mu2>
            </ode>
          </friction>
        </surface>
      </collision>
      <visual name='visual'>
        <geometry>
          <sphere>
            <radius>0.25</radius>
          </sphere>
        </geometry>
        <material>
          <ambient>1 1 1 1</ambient>
          <diffuse>1 1 1 1</diffuse>
          <specular>0.1 0.1 0.1 1</specular>
          <emissive>0 0 0 0</emissive>
        </material>
      </visual>
      <velocity_decay>
        <linear>0</linear>
        <angular>0</angular>
      </velocity_decay>
    </link>
    <joint name='spring_joint_2' type='prismatic'>
      <parent>tactile_2</parent>
      <child>spring_2</child>
      <axis>
        <xyz>0 0 1</xyz>
        <limit>
          <lower>-1e+16</lower>
          <upper>1e+16</upper>
        </limit>
      </axis>
    </joint>
    <link name='tactile_2'>
      <pose>-1 1.5 0.4 0 -0 0</pose>
      <inertial>
        <mass>0.001</mass>
      </inertial>
      <collision name='square_collision'>
        <geometry>
          <box>
            <size>0.5 0.5 0.01</size>
          </box>
        </geometry>
        <surface>
          <friction>
            <ode>
              <mu>0</mu>
              <mu2>0</mu2>
            </ode>
          </friction>
        </surface>
      </collision>
      <visual name='visual'>
        <geometry>
          <box>
            <size>0.5 0.5 0.01</size>
          </box>
        </geometry>
        <material>
          <ambient>1 0 0 1</ambient>
          <diffuse>1 0 0 1</diffuse>
          <specular>0.1 0.1 0.1 1</specular>
          <emissive>0 0 0 0</emissive>
        </material>
      </visual>
      <velocity_decay>
        <linear>0</linear>
        <angular>0</angular>
      </velocity_decay>
    </link>
    <joint name='tactile_joint_2' type='prismatic'>
      <parent>plane</parent>
      <child>tactile_2</child>
      <axis>
        <xyz>0 0 1</xyz>
        <limit>
          <lower>-1e+16</lower>
          <upper>1e+16</upper>
        </limit>
      </axis>
    </joint>
    <link name='spring_3'>
      <pose>-0.5 1.5 1.3 0 -0 0</pose>
      <inertial>
        <mass>0.001</mass>
      </inertial>
      <collision name='sphere_collision'>
        <geometry>
          <sphere>
            <radius>0.25</radius>
          </sphere>
        </geometry>
        <surface>
          <friction>
            <ode>
              <mu>0</mu>
              <mu2>0</mu2>
            </ode>
          </friction>
        </surface>
      </collision>
      <visual name='visual'>
        <geometry>
          <sphere>
            <radius>0.25</radius>
          </sphere>
        </geometry>
        <material>
          <ambient>1 1 1 1</ambient>
          <diffuse>1 1 1 1</diffuse>
          <specular>0.1 0.1 0.1 1</specular>
          <emissive>0 0 0 0</emissive>
        </material>
      </visual>
      <velocity_decay>
        <linear>0</linear>
        <angular>0</angular>
      </velocity_decay>
    </link>
    <joint name='spring_joint_3' type='prismatic'>
      <parent>tactile_3</parent>
      <child>spring_3</child>
      <axis>
        <xyz>0 0 1</xyz>
        <limit>
          <lower>-1e+16</lower>
          <upper>1e+16</upper>
        </limit>
      </axis>
    </joint>
    <link name='tactile_3'>
      <pose>-0.5 1.5 0.4 0 -0 0</pose>
      <inertial>
        <mass>0.001</mass>
      </inertial>
      <collision name='square_collision'>
        <geometry>
          <box>
            <size>0.5 0.5 0.01</size>
          </box>
        </geometry>
        <surface>
          <friction>
            <ode>
              <mu>0</mu>
              <mu2>0</mu2>
            </ode>
          </friction>
        </surface>
      </collision>
      <visual name='visual'>
        <geometry>
          <box>
            <size>0.5 0.5 0.01</size>
          </box>
        </geometry>
        <material>
          <ambient>1 0 0 1</ambient>
          <diffuse>1 0 0 1</diffuse>
          <specular>0.1 0.1 0.1 1</specular>
          <emissive>0 0 0 0</emissive>
        </material>
      </visual>
      <velocity_decay>
        <linear>0</linear>
        <angular>0</angular>
      </velocity_decay>
    </link>
    <joint name='tactile_joint_3' type='prismatic'>
      <parent>plane</parent>
      <child>tactile_3</child>
      <axis>
        <xyz>0 0 1</xyz>
        <limit>
          <lower>-1e+16</lower>
          <upper>1e+16</upper>
        </limit>
      </axis>
    </joint>
    <link name='spring_4'>
      <pose>0 1.5 1.3 0 -0 0</pose>
      <inertial>
        <mass>0.001</mass>
      </inertial>
      <collision name='sphere_collision'>
        <geometry>
          <sphere>
            <radius>0.25</radius>
          </sphere>
        </geometry>
        <surface>
          <friction>
            <ode>
              <mu>0</mu>
              <mu2>0</mu2>
            </ode>
          </friction>
        </surface>
      </collision>
      <visual name='visual'>
        <geometry>
          <sphere>
            <radius>0.25</radius>
          </sphere>
        </geometry>
        <material>
          <ambient>1 1 1 1</ambient>
          <diffuse>1 1 1 1</diffuse>
          <specular>0.1 0.1 0.1 1</specular>
          <emissive>0 0 0 0</emissive>
        </material>
      </visual>
      <velocity_decay>
        <linear>0</linear>
        <angular>0</angular>
      </velocity_decay>
    </link>
    <joint name='spring_joint_4' type='prismatic'>
      <parent>tactile_4</parent>
      <child>spring_4</child>
      <axis>
        <xyz>0 0 1</xyz>
        <limit>
          <lower>-1e+16</lower>
          <upper>1e+16</upper>
        </limit>
      </axis>
    </joint>
    <link name='tactile_4'>
      <pose>0 1.5 0.4 0 -0 0</pose>
      <inertial>
        <mass>0.001</mass>
      </inertial>
      <collision name='square_collision'>
        <geometry>
          <box>
            <size>0.5 0.5 0.01</size>
          </box>
        </geometry>
        <surface>
          <friction>
            <ode>
              <mu>0</mu>
              <mu2>0</mu2>
            </ode>
          </friction>
        </surface>
      </collision>
      <visual name='visual'>
        <geometry>
          <box>
            <size>0.5 0.5 0.01</size>
          </box>
        </geometry>
        <material>
          <ambient>1 0 0 1</ambient>
          <diffuse>1 0 0 1</diffuse>
          <specular>0.1 0.1 0.1 1</specular>
          <emissive>0 0 0 0</emissive>
        </material>
      </visual>
      <velocity_decay>
        <linear>0</linear>
        <angular>0</angular>
      </velocity_decay>
    </link>
    <joint name='tactile_joint_4' type='prismatic'>
      <parent>plane</parent>
      <child>tactile_4</child>
      <axis>
        <xyz>0 0 1</xyz>
        <limit>
          <lower>-1e+16</lower>
          <upper>1e+16</upper>
        </limit>
      </axis>
    </joint>
    <link name='spring_5'>
      <pose>0.5 1.5 1.3 0 -0 0</pose>
      <inertial>
        <mass>0.001</mass>
      </inertial>
      <collision name='sphere_collision'>
        <geometry>
          <sphere>
            <radius>0.25</radius>
          </sphere>
        </geometry>
        <surface>
          <friction>
            <ode>
              <mu>0</mu>
              <mu2>0</mu2>
            </ode>
          </friction>
        </surface>
      </collision>
      <visual name='visual'>
        <geometry>
          <sphere>
            <radius>0.25</radius>
          </sphere>
        </geometry>
        <material>
          <ambient>1 1 1 1</ambient>
          <diffuse>1 1 1 1</diffuse>
          <specular>0.1 0.1 0.1 1</specular>
          <emissive>0 0 0 0</emissive>
        </material>
      </visual>
      <velocity_decay>
        <linear>0</linear>
        <angular>0</angular>
      </velocity_decay>
    </link>
    <joint name='spring_joint_5' type='prismatic'>
      <parent>tactile_5</parent>
      <child>spring_5</child>
      <axis>
        <xyz>0 0 1</xyz>
        <limit>
          <lower>-1e+16</lower>
          <upper>1e+16</upper>
        </limit>
      </axis>
    </joint>
    <link name='tactile_5'>
      <pose>0.5 1.5 0.4 0 -0 0</pose>
      <inertial>
        <mass>0.001</mass>
      </inertial>
      <collision name='square_collision'>
        <geometry>
          <box>
            <size>0.5 0.5 0.01</size>
          </box>
        </geometry>
        <surface>
          <friction>
            <ode>
              <mu>0</mu>
              <mu2>0</mu2>
            </ode>
          </friction>
        </surface>
      </collision>
      <visual name='visual'>
        <geometry>
          <box>
            <size>0.5 0.5 0.01</size>
          </box>
        </geometry>
        <material>
          <ambient>1 0 0 1</ambient>
          <diffuse>1 0 0 1</diffuse>
          <specular>0.1 0.1 0.1 1</specular>
          <emissive>0 0 0 0</emissive>
        </material>
      </visual>
      <velocity_decay>
        <linear>0</linear>
        <angular>0</angular>
      </velocity_decay>
    </link>
    <joint name='tactile_joint_5' type='prismatic'>
      <parent>plane</parent>
      <child>tactile_5</child>
      <axis>
        <xyz>0 0 1</xyz>
        <limit>
          <lower>-1e+16</lower>
          <upper>1e+16</upper>
        </limit>
      </axis>
    </joint>
    <link name='spring_6'>
      <pose>1 1.5 1.3 0 -0 0</pose>
      <inertial>
        <mass>0.001</mass>
      </inertial>
      <collision name='sphere_collision'>
        <geometry>
          <sphere>
            <radius>0.25</radius>
          </sphere>
        </geometry>
        <surface>
          <friction>
            <ode>
              <mu>0</mu>
              <mu2>0</mu2>
            </ode>
          </friction>
        </surface>
      </collision>
      <visual name='visual'>
        <geometry>
          <sphere>
            <radius>0.25</radius>
          </sphere>
        </geometry>
        <material>
          <ambient>1 1 1 1</ambient>
          <diffuse>1 1 1 1</diffuse>
          <specular>0.1 0.1 0.1 1</specular>
          <emissive>0 0 0 0</emissive>
        </material>
      </visual>
      <velocity_decay>
        <linear>0</linear>
        <angular>0</angular>
      </velocity_decay>
    </link>
    <joint name='spring_joint_6' type='prismatic'>
      <parent>tactile_6</parent>
      <child>spring_6</child>
      <axis>
        <xyz>0 0 1</xyz>
        <limit>
          <lower>-1e+16</lower>
          <upper>1e+16</upper>
        </limit>
      </axis>
    </joint>
    <link name='tactile_6'>
      <pose>1 1.5 0.4 0 -0 0</pose>
      <inertial>
        <mass>0.001</mass>
      </inertial>
      <collision name='square_collision'>
        <geometry>
          <box>
            <size>0.5 0.5 0.01</size>
          </box>
        </geometry>
        <surface>
          <friction>
            <ode>
              <mu>0</mu>
              <mu2>0</mu2>
            </ode>
          </friction>
        </surface>
      </collision>
      <visual name='visual'>
        <geometry>
          <box>
            <size>0.5 0.5 0.01</size>
          </box>
        </geometry>
        <material>
          <ambient>1 0 0 1</ambient>
          <diffuse>1 0 0 1</diffuse>
          <specular>0.1 0.1 0.1 1</specular>
          <emissive>0 0 0 0</emissive>
        </material>
      </visual>
      <velocity_decay>
        <linear>0</linear>
        <angular>0</angular>
      </velocity_decay>
    </link>
    <joint name='tactile_joint_6' type='prismatic'>
      <parent>plane</parent>
      <child>tactile_6</child>
      <axis>
        <xyz>0 0 1</xyz>
        <limit>
          <lower>-1e+16</lower>
          <upper>1e+16</upper>
        </limit>
      </axis>
    </joint>
    <link name='spring_7'>
      <pose>1.5 1.5 1.3 0 -0 0</pose>
      <inertial>
        <mass>0.001</mass>
      </inertial>
      <collision name='sphere_collision'>
        <geometry>
          <sphere>
            <radius>0.25</radius>
          </sphere>
        </geometry>
        <surface>
          <friction>
            <ode>
              <mu>0</mu>
              <mu2>0</mu2>
            </ode>
          </friction>
        </surface>
      </collision>
      <visual name='visual'>
        <geometry>
          <sphere>
            <radius>0.25</radius>
          </sphere>
        </geometry>
        <material>
          <ambient>1 1 1 1</ambient>
          <diffuse>1 1 1 1</diffuse>
          <specular>0.1 0.1 0.1 1</specular>
          <emissive>0 0 0 0</emissive>
        </material>
      </visual>
      <velocity_decay>
        <linear>0</linear>
        <angular>0</angular>
      </velocity_decay>
    </link>
    <joint name='spring_joint_7' type='prismatic'>
      <parent>tactile_7</parent>
      <child>spring_7</child>
      <axis>
        <xyz>0 0 1</xyz>
        <limit>
          <lower>-1e+16</lower>
          <upper>1e+16</upper>
        </limit>
      </axis>
    </joint>
    <link name='tactile_7'>
      <pose>1.5 1.5 0.4 0 -0 0</pose>
      <inertial>
        <mass>0.001</mass>
      </inertial>
      <collision name='square_collision'>
        <geometry>
          <box>
            <size>0.5 0.5 0.01</size>
          </box>
        </geometry>
        <surface>
          <friction>
            <ode>
              <mu>0</mu>
              <mu2>0</mu2>
            </ode>
          </friction>
        </surface>
      </collision>
      <visual name='visual'>
        <geometry>
          <box>
            <size>0.5 0.5 0.01</size>
          </box>
        </geometry>
        <material>
          <ambient>1 0 0 1</ambient>
          <diffuse>1 0 0 1</diffuse>
          <specular>0.1 0.1 0.1 1</specular>
          <emissive>0 0 0 0</emissive>
        </material>
      </visual>
      <velocity_decay>
        <linear>0</linear>
        <angular>0</angular>
      </velocity_decay>
    </link>
    <joint name='tactile_joint_7' type='prismatic'>
      <parent>plane</parent>
      <child>tactile_7</child>
      <axis>
        <xyz>0 0 1</xyz>
        <limit>
          <lower>-1e+16</lower>
          <upper>1e+16</upper>
        </limit>
      </axis>
    </joint>
    <link name='spring_8'>
      <pose>-1.5 1 1.3 0 -0 0</pose>
      <inertial>
        <mass>0.001</mass>
      </inertial>
      <collision name='sphere_collision'>
        <geometry>
          <sphere>
            <radius>0.25</radius>
          </sphere>
        </geometry>
        <surface>
          <friction>
            <ode>
              <mu>0</mu>
              <mu2>0</mu2>
            </ode>
          </friction>
        </surface>
      </collision>
      <visual name='visual'>
        <geometry>
          <sphere>
            <radius>0.25</radius>
          </sphere>
        </geometry>
        <material>
          <ambient>1 1 1 1</ambient>
          <diffuse>1 1 1 1</diffuse>
          <specular>0.1 0.1 0.1 1</specular>
          <emissive>0 0 0 0</emissive>
        </material>
      </visual>
      <velocity_decay>
        <linear>0</linear>
        <angular>0</angular>
      </velocity_decay>
    </link>
    <joint name='spring_joint_8' type='prismatic'>
      <parent>tactile_8</parent>
      <child>spring_8</child>
      <axis>
        <xyz>0 0 1</xyz>
        <limit>
          <lower>-1e+16</lower>
          <upper>1e+16</upper>
        </limit>
      </axis>
    </joint>
    <link name='tactile_8'>
      <pose>-1.5 1 0.4 0 -0 0</pose>
      <inertial>
        <mass>0.001</mass>
      </inertial>
      <collision name='square_collision'>
        <geometry>
          <box>
            <size>0.5 0.5 0.01</size>
          </box>
        </geometry>
        <surface>
          <friction>
            <ode>
              <mu>0</mu>
              <mu2>0</mu2>
            </ode>
          </friction>
        </surface>
      </collision>
      <visual name='visual'>
        <geometry>
          <box>
            <size>0.5 0.5 0.01</size>
          </box>
        </geometry>
        <material>
          <ambient>1 0 0 1</ambient>
          <diffuse>1 0 0 1</diffuse>
          <specular>0.1 0.1 0.1 1</specular>
          <emissive>0 0 0 0</emissive>
        </material>
      </visual>
      <velocity_decay>
        <linear>0</linear>
        <angular>0</angular>
      </velocity_decay>
    </link>
    <joint name='tactile_joint_8' type='prismatic'>
      <parent>plane</parent>
      <child>tactile_8</child>
      <axis>
        <xyz>0 0 1</xyz>
        <limit>
          <lower>-1e+16</lower>
          <upper>1e+16</upper>
        </limit>
      </axis>
    </joint>
    <link name='spring_9'>
      <pose>-1 1 1.3 0 -0 0</pose>
      <inertial>
        <mass>0.001</mass>
      </inertial>
      <collision name='sphere_collision'>
        <geometry>
          <sphere>
            <radius>0.25</radius>
          </sphere>
        </geometry>
        <surface>
          <friction>
            <ode>
              <mu>0</mu>
              <mu2>0</mu2>
            </ode>
          </friction>
        </surface>
      </collision>
      <visual name='visual'>
        <geometry>
          <sphere>
            <radius>0.25</radius>
          </sphere>
        </geometry>
        <material>
          <ambient>1 1 1 1</ambient>
          <diffuse>1 1 1 1</diffuse>
          <specular>0.1 0.1 0.1 1</specular>
          <emissive>0 0 0 0</emissive>
        </material>
      </visual>
      <velocity_decay>
        <linear>0</linear>
        <angular>0</angular>
      </velocity_decay>
    </link>
    <joint name='spring_joint_9' type='prismatic'>
      <parent>tactile_9</parent>
      <child>spring_9</child>
      <axis>
        <xyz>0 0 1</xyz>
        <limit>
          <lower>-1e+16</lower>
          <upper>1e+16</upper>
        </limit>
      </axis>
    </joint>
    <link name='tactile_9'>
      <pose>-1 1 0.4 0 -0 0</pose>
      <inertial>
        <mass>0.001</mass>
      </inertial>
      <collision name='square_collision'>
        <geometry>
          <box>
            <size>0.5 0.5 0.01</size>
          </box>
        </geometry>
        <surface>
          <friction>
            <ode>
              <mu>0</mu>
              <mu2>0</mu2>
            </ode>
          </friction>
        </surface>
      </collision>
      <visual name='visual'>
        <geometry>
          <box>
            <size>0.5 0.5 0.01</size>
          </box>
        </geometry>
        <material>
          <ambient>1 0 0 1</ambient>
          <diffuse>1 0 0 1</diffuse>
          <specular>0.1 0.1 0.1 1</specular>
          <emissive>0 0 0 0</emissive>
        </material>
      </visual>
      <velocity_decay>
        <linear>0</linear>
        <angular>0</angular>
      </velocity_decay>
    </link>
    <joint name='tactile_joint_9' type='prismatic'>
      <parent>plane</parent>
      <child>tactile_9</child>
      <axis>
        <xyz>0 0 1</xyz>
        <limit>
          <lower>-1e+16</lower>
          <upper>1e+16</upper>
        </limit>
      </axis>
    </joint>
    <link name='spring_10'>
      <pose>-0.5 1 1.3 0 -0 0</pose>
      <inertial>
        <mass>0.001</mass>
      </inertial>
      <collision name='sphere_collision'>
        <geometry>
          <sphere>
            <radius>0.25</radius>
          </sphere>
        </geometry>
        <surface>
          <friction>
            <ode>
              <mu>0</mu>
              <mu2>0</mu2>
            </ode>
          </friction>
        </surface>
      </collision>
      <visual name='visual'>
        <geometry>
          <sphere>
            <radius>0.25</radius>
          </sphere>
        </geometry>
        <material>
          <ambient>1 1 1 1</ambient>
          <diffuse>1 1 1 1</diffuse>
          <specular>0.1 0.1 0.1 1</specular>
          <emissive>0 0 0 0</emissive>
        </material>
      </visual>
      <velocity_decay>
        <linear>0</linear>
        <angular>0</angular>
      </velocity_decay>
    </link>
    <joint name='spring_joint_10' type='prismatic'>
      <parent>tactile_10</parent>
      <child>spring_10</child>
      <axis>
        <xyz>0 0 1</xyz>
        <limit>
          <lower>-1e+16</lower>
          <upper>1e+16</upper>
        </limit>
      </axis>
    </joint>
    <link name='tactile_10'>
      <pose>-0.5 1 0.4 0 -0 0</pose>
      <inertial>
        <mass>0.001</mass>
      </inertial>
      <collision name='square_collision'>
        <geometry>
          <box>
            <size>0.5 0.5 0.01</size>
          </box>
        </geometry>
        <surface>
          <friction>
            <ode>
              <mu>0</mu>
              <mu2>0</mu2>
            </ode>
          </friction>
        </surface>
      </collision>
      <visual name='visual'>
        <geometry>
          <box>
            <size>0.5 0.5 0.01</size>
          </box>
        </geometry>
        <material>
          <ambient>1 0 0 1</ambient>
          <diffuse>1 0 0 1</diffuse>
          <specular>0.1 0.1 0.1 1</specular>
          <emissive>0 0 0 0</emissive>
        </material>
      </visual>
      <velocity_decay>
        <linear>0</linear>
        <angular>0</angular>
      </velocity_decay>
    </link>
    <joint name='tactile_joint_10' type='prismatic'>
      <parent>plane</parent>
      <child>tactile_10</child>
      <axis>
        <xyz>0 0 1</xyz>
        <limit>
          <lower>-1e+16</lower>
          <upper>1e+16</upper>
        </limit>
      </axis>
    </joint>
    <link name='spring_11'>
      <pose>0 1 1.3 0 -0 0</pose>
      <inertial>
        <mass>0.001</mass>
      </inertial>
      <collision name='sphere_collision'>
        <geometry>
          <sphere>
            <radius>0.25</radius>
          </sphere>
        </geometry>
        <surface>
          <friction>
            <ode>
              <mu>0</mu>
              <mu2>0</mu2>
            </ode>
          </friction>
        </surface>
      </collision>
      <visual name='visual'>
        <geometry>
          <sphere>
            <radius>0.25</radius>
          </sphere>
        </geometry>
        <material>
          <ambient>1 1 1 1</ambient>
          <diffuse>1 1 1 1</diffuse>
          <specular>0.1 0.1 0.1 1</specular>
          <emissive>0 0 0 0</emissive>
        </material>
      </visual>
      <velocity_decay>
        <linear>0</linear>
        <angular>0</angular>
      </velocity_decay>
    </link>
    <joint name='spring_joint_11' type='prismatic'>
      <parent>tactile_11</parent>
      <child>spring_11</child>
      <axis>
        <xyz>0 0 1</xyz>
        <limit>
          <lower>-1e+16</lower>
          <upper>1e+16</upper>
        </limit>
      </axis>
    </joint>
    <link name='tactile_11'>
      <pose>0 1 0.4 0 -0 0</pose>
      <inertial>
        <mass>0.001</mass>
      </inertial>
      <collision name='square_collision'>
        <geometry>
          <box>
            <size>0.5 0.5 0.01</size>
          </box>
        </geometry>
        <surface>
          <friction>
            <ode>
              <mu>0</mu>
              <mu2>0</mu2>
            </ode>
          </friction>
        </surface>
      </collision>
      <visual name='visual'>
        <geometry>
          <box>
            <size>0.5 0.5 0.01</size>
          </box>
        </geometry>
        <material>
          <ambient>1 0 0 1</ambient>
          <diffuse>1 0 0 1</diffuse>
          <specular>0.1 0.1 0.1 1</specular>
          <emissive>0 0 0 0</emissive>
        </material>
      </visual>
      <velocity_decay>
        <linear>0</linear>
        <angular>0</angular>
      </velocity_decay>
    </link>
    <joint name='tactile_joint_11' type='prismatic'>
      <parent>plane</parent>
      <child>tactile_11</child>
      <axis>
        <xyz>0 0 1</xyz>
        <limit>
          <lower>-1e+16</lower>
          <upper>1e+16</upper>
        </limit>
      </axis>
    </joint>
    <link name='spring_12'>
      <pose>0.5 1 1.3 0 -0 0</pose>
      <inertial>
        <mass>0.001</mass>
      </inertial>
      <collision name='sphere_collision'>
        <geometry>
          <sphere>
            <radius>0.25</radius>
          </sphere>
        </geometry>
        <surface>
          <friction>
            <ode>
              <mu>0</mu>
              <mu2>0</mu2>
            </ode>
          </friction>
        </surface>
      </collision>
      <visual name='visual'>
        <geometry>
          <sphere>
            <radius>0.25</radius>
          </sphere>
        </geometry>
        <material>
          <ambient>1 1 1 1</ambient>
          <diffuse>1 1 1 1</diffuse>
          <specular>0.1 0.1 0.1 1</specular>
          <emissive>0 0 0 0</emissive>
        </material>
      </visual>
      <velocity_decay>
        <linear>0</linear>
        <angular>0</angular>
      </velocity_decay>
    </link>
    <joint name='spring_joint_12' type='prismatic'>
      <parent>tactile_12</parent>
      <child>spring_12</child>
      <axis>
        <xyz>0 0 1</xyz>
        <limit>
          <lower>-1e+16</lower>
          <upper>1e+16</upper>
        </limit>
      </axis>
    </joint>
    <link name='tactile_12'>
      <pose>0.5 1 0.4 0 -0 0</pose>
      <inertial>
        <mass>0.001</mass>
      </inertial>
      <collision name='square_collision'>
        <geometry>
          <box>
            <size>0.5 0.5 0.01</size>
          </box>
        </geometry>
        <surface>
          <friction>
            <ode>
              <mu>0</mu>
              <mu2>0</mu2>
            </ode>
          </friction>
        </surface>
      </collision>
      <visual name='visual'>
        <geometry>
          <box>
            <size>0.5 0.5 0.01</size>
          </box>
        </geometry>
        <material>
          <ambient>1 0 0 1</ambient>
          <diffuse>1 0 0 1</diffuse>
          <specular>0.1 0.1 0.1 1</specular>
          <emissive>0 0 0 0</emissive>
        </material>
      </visual>
      <velocity_decay>
        <linear>0</linear>
        <angular>0</angular>
      </velocity_decay>
    </link>
    <joint name='tactile_joint_12' type='prismatic'>
      <parent>plane</parent>
      <child>tactile_12</child>
      <axis>
        <xyz>0 0 1</xyz>
        <limit>
          <lower>-1e+16</lower>
          <upper>1e+16</upper>
        </limit>
      </axis>
    </joint>
    <link name='spring_13'>
      <pose>1 1 1.3 0 -0 0</pose>
      <inertial>
        <mass>0.001</mass>
      </inertial>
      <collision name='sphere_collision'>
        <geometry>
          <sphere>
            <radius>0.25</radius>
          </sphere>
        </geometry>
        <surface>
          <friction>
            <ode>
              <mu>0</mu>
              <mu2>0</mu2>
            </ode>
          </friction>
        </surface>
      </collision>
      <visual name='visual'>
        <geometry>
          <sphere>
            <radius>0.25</radius>
          </sphere>
        </geometry>
        <material>
          <ambient>1 1 1 1</ambient>
          <diffuse>1 1 1 1</diffuse>
          <specular>0.1 0.1 0.1 1</specular>
          <emissive>0 0 0 0</emissive>
        </material>
      </visual>
      <velocity_decay>
        <linear>0</linear>
        <angular>0</angular>
      </velocity_decay>
    </link>
    <joint name='spring_joint_13' type='prismatic'>
      <parent>tactile_13</parent>
      <child>spring_13</child>
      <axis>
        <xyz>0 0 1</xyz>
        <limit>
          <lower>-1e+16</lower>
          <upper>1e+16</upper>
        </limit>
      </axis>
    </joint>
    <link name='tactile_13'>
      <pose>1 1 0.4 0 -0 0</pose>
      <inertial>
        <mass>0.001</mass>
      </inertial>
      <collision name='square_collision'>
        <geometry>
          <box>
            <size>0.5 0.5 0.01</size>
          </box>
        </geometry>
        <surface>
          <friction>
            <ode>
              <mu>0</mu>
              <mu2>0</mu2>
            </ode>
          </friction>
        </surface>
      </collision>
      <visual name='visual'>
        <geometry>
          <box>
            <size>0.5 0.5 0.01</size>
          </box>
        </geometry>
        <material>
          <ambient>1 0 0 1</ambient>
          <diffuse>1 0 0 1</diffuse>
          <specular>0.1 0.1 0.1 1</specular>
          <emissive>0 0 0 0</emissive>
        </material>
      </visual>
      <velocity_decay>
        <linear>0</linear>
        <angular>0</angular>
      </velocity_decay>
    </link>
    <joint name='tactile_joint_13' type='prismatic'>
      <parent>plane</parent>
      <child>tactile_13</child>
      <axis>
        <xyz>0 0 1</xyz>
        <limit>
          <lower>-1e+16</lower>
          <upper>1e+16</upper>
        </limit>
      </axis>
    </joint>
    <link name='spring_14'>
      <pose>1.5 1 1.3 0 -0 0</pose>
      <inertial>
        <mass>0.001</mass>
      </inertial>
      <collision name='sphere_collision'>
        <geometry>
          <sphere>
            <radius>0.25</radius>
          </sphere>
        </geometry>
        <surface>
          <friction>
            <ode>
              <mu>0</mu>
              <mu2>0</mu2>
            </ode>
          </friction>
        </surface>
      </collision>
      <visual name='visual'>
        <geometry>
          <sphere>
            <radius>0.25</radius>
          </sphere>
        </geometry>
        <material>
          <ambient>1 1 1 1</ambient>
          <diffuse>1 1 1 1</diffuse>
          <specular>0.1 0.1 0.1 1</specular>
          <emissive>0 0 0 0</emissive>
        </material>
      </visual>
      <velocity_decay>
        <linear>0</linear>
        <angular>0</angular>
      </velocity_decay>
    </link>
    <joint name='spring_joint_14' type='prismatic'>
      <parent>tactile_14</parent>
      <child>spring_14</child>
      <axis>
        <xyz>0 0 1</xyz>
        <limit>
          <lower>-1e+16</lower>
          <upper>1e+16</upper>
        </limit>
      </axis>
    </joint>
    <link name='tactile_14'>
      <pose>1.5 1 0.4 0 -0 0</pose>
      <inertial>
        <mass>0.001</mass>
      </inertial>
      <collision name='square_collision'>
        <geometry>
          <box>
            <size>0.5 0.5 0.01</size>
          </box>
        </geometry>
        <surface>
          <friction>
            <ode>
              <mu>0</mu>
              <mu2>0</mu2>
            </ode>
          </friction>
        </surface>
      </collision>
      <visual name='visual'>
        <geometry>
          <box>
            <size>0.5 0.5 0.01</size>
          </box>
        </geometry>
        <material>
          <ambient>1 0 0 1</ambient>
          <diffuse>1 0 0 1</diffuse>
          <specular>0.1 0.1 0.1 1</specular>
          <emissive>0 0 0 0</emissive>
        </material>
      </visual>
      <velocity_decay>
        <linear>0</linear>
        <angular>0</angular>
      </velocity_decay>
    </link>
    <joint name='tactile_joint_14' type='prismatic'>
      <parent>plane</parent>
      <child>tactile_14</child>
      <axis>
        <xyz>0 0 1</xyz>
        <limit>
          <lower>-1e+16</lower>
          <upper>1e+16</upper>
        </limit>
      </axis>
    </joint>
    <link name='spring_15'>
      <pose>-1.5 0.5 1.3 0 -0 0</pose>
      <inertial>
        <mass>0.001</mass>
      </inertial>
      <collision name='sphere_collision'>
        <geometry>
          <sphere>
            <radius>0.25</radius>
          </sphere>
        </geometry>
        <surface>
          <friction>
            <ode>
              <mu>0</mu>
              <mu2>0</mu2>
            </ode>
          </friction>
        </surface>
      </collision>
      <visual name='visual'>
        <geometry>
          <sphere>
            <radius>0.25</radius>
          </sphere>
        </geometry>
        <material>
          <ambient>1 1 1 1</ambient>
          <diffuse>1 1 1 1</diffuse>
          <specular>0.1 0.1 0.1 1</specular>
          <emissive>0 0 0 0</emissive>
        </material>
      </visual>
      <velocity_decay>
        <linear>0</linear>
        <angular>0</angular>
      </velocity_decay>
    </link>
    <joint name='spring_joint_15' type='prismatic'>
      <parent>tactile_15</parent>
      <child>spring_15</child>
      <axis>
        <xyz>0 0 1</xyz>
        <limit>
          <lower>-1e+16</lower>
          <upper>1e+16</upper>
        </limit>
      </axis>
    </joint>
    <link name='tactile_15'>
      <pose>-1.5 0.5 0.4 0 -0 0</pose>
      <inertial>
        <mass>0.001</mass>
      </inertial>
      <collision name='square_collision'>
        <geometry>
          <box>
            <size>0.5 0.5 0.01</size>
          </box>
        </geometry>
        <surface>
          <friction>
            <ode>
              <mu>0</mu>
              <mu2>0</mu2>
            </ode>
          </friction>
        </surface>
      </collision>
      <visual name='visual'>
        <geometry>
          <box>
            <size>0.5 0.5 0.01</size>
          </box>
        </geometry>
        <material>
          <ambient>1 0 0 1</ambient>
          <diffuse>1 0 0 1</diffuse>
          <specular>0.1 0.1 0.1 1</specular>
          <emissive>0 0 0 0</emissive>
        </material>
      </visual>
      <velocity_decay>
        <linear>0</linear>
        <angular>0</angular>
      </velocity_decay>
    </link>
    <joint name='tactile_joint_15' type='prismatic'>
      <parent>plane</parent>
      <child>tactile_15</child>
      <axis>
        <xyz>0 0 1</xyz>
        <limit>
          <lower>-1e+16</lower>
          <upper>1e+16</upper>
        </limit>
      </axis>
    </joint>
    <link name='spring_16'>
      <pose>-1 0.5 1.3 0 -0 0</pose>
      <inertial>
        <mass>0.001</mass>
      </inertial>
      <collision name='sphere_collision'>
        <geometry>
          <sphere>
            <radius>0.25</radius>
          </sphere>
        </geometry>
        <surface>
          <friction>
            <ode>
              <mu>0</mu>
              <mu2>0</mu2>
            </ode>
          </friction>
        </surface>
      </collision>
      <visual name='visual'>
        <geometry>
          <sphere>
            <radius>0.25</radius>
          </sphere>
        </geometry>
        <material>
          <ambient>1 1 1 1</ambient>
          <diffuse>1 1 1 1</diffuse>
          <specular>0.1 0.1 0.1 1</specular>
          <emissive>0 0 0 0</emissive>
        </material>
      </visual>
      <velocity_decay>
        <linear>0</linear>
        <angular>0</angular>
      </velocity_decay>
    </link>
    <joint name='spring_joint_16' type='prismatic'>
      <parent>tactile_16</parent>
      <child>spring_16</child>
      <axis>
        <xyz>0 0 1</xyz>
        <limit>
          <lower>-1e+16</lower>
          <upper>1e+16</upper>
        </limit>
      </axis>
    </joint>
    <link name='tactile_16'>
      <pose>-1 0.5 0.4 0 -0 0</pose>
      <inertial>
        <mass>0.001</mass>
      </inertial>
      <collision name='square_collision'>
        <geometry>
          <box>
            <size>0.5 0.5 0.01</size>
          </box>
        </geometry>
        <surface>
          <friction>
            <ode>
              <mu>0</mu>
              <mu2>0</mu2>
            </ode>
          </friction>
        </surface>
      </collision>
      <visual name='visual'>
        <geometry>
          <box>
            <size>0.5 0.5 0.01</size>
          </box>
        </geometry>
        <material>
          <ambient>1 0 0 1</ambient>
          <diffuse>1 0 0 1</diffuse>
          <specular>0.1 0.1 0.1 1</specular>
          <emissive>0 0 0 0</emissive>
        </material>
      </visual>
      <velocity_decay>
        <linear>0</linear>
        <angular>0</angular>
      </velocity_decay>
    </link>
    <joint name='tactile_joint_16' type='prismatic'>
      <parent>plane</parent>
      <child>tactile_16</child>
      <axis>
        <xyz>0 0 1</xyz>
        <limit>
          <lower>-1e+16</lower>
          <upper>1e+16</upper>
        </limit>
      </axis>
    </joint>
    <link name='spring_17'>
      <pose>-0.5 0.5 1.3 0 -0 0</pose>
      <inertial>
        <mass>0.001</mass>
      </inertial>
      <collision name='sphere_collision'>
        <geometry>
          <sphere>
            <radius>0.25</radius>
          </sphere>
        </geometry>
        <surface>
          <friction>
            <ode>
              <mu>0</mu>
              <mu2>0</mu2>
            </ode>
          </friction>
        </surface>
      </collision>
      <visual name='visual'>
        <geometry>
          <sphere>
            <radius>0.25</radius>
          </sphere>
        </geometry>
        <material>
          <ambient>1 1 1 1</ambient>
          <diffuse>1 1 1 1</diffuse>
          <specular>0.1 0.1 0.1 1</specular>
          <emissive>0 0 0 0</emissive>
        </material>
      </visual>
      <velocity_decay>
        <linear>0</linear>
        <angular>0</angular>
      </velocity_decay>
    </link>
    <joint name='spring_joint_17' type='prismatic'>
      <parent>tactile_17</parent>
      <child>spring_17</child>
      <axis>
        <xyz>0 0 1</xyz>
        <limit>
          <lower>-1e+16</lower>
          <upper>1e+16</upper>
        </limit>
      </axis>
    </joint>
    <link name='tactile_17'>
      <pose>-0.5 0.5 0.4 0 -0 0</pose>
      <inertial>
        <mass>0.001</mass>
      </inertial>
      <collision name='square_collision'>
        <geometry>
          <box>
            <size>0.5 0.5 0.01</size>
          </box>
        </geometry>
        <surface>
          <friction>
            <ode>
              <mu>0</mu>
              <mu2>0</mu2>
            </ode>
          </friction>
        </surface>
      </collision>
      <visual name='visual'>
        <geometry>
          <box>
            <size>0.5 0.5 0.01</size>
          </box>
        </geometry>
        <material>
          <ambient>1 0 0 1</ambient>
          <diffuse>1 0 0 1</diffuse>
          <specular>0.1 0.1 0.1 1</specular>
          <emissive>0 0 0 0</emissive>
        </material>
      </visual>
      <velocity_decay>
        <linear>0</linear>
        <angular>0</angular>
      </velocity_decay>
    </link>
    <joint name='tactile_joint_17' type='prismatic'>
      <parent>plane</parent>
      <child>tactile_17</child>
      <axis>
        <xyz>0 0 1</xyz>
        <limit>
          <lower>-1e+16</lower>
          <upper>1e+16</upper>
        </limit>
      </axis>
    </joint>
    <link name='spring_18'>
      <pose>0 0.5 1.3 0 -0 0</pose>
      <inertial>
        <mass>0.001</mass>
      </inertial>
      <collision name='sphere_collision'>
        <geometry>
          <sphere>
            <radius>0.25</radius>
          </sphere>
        </geometry>
        <surface>
          <friction>
            <ode>
              <mu>0</mu>
              <mu2>0</mu2>
            </ode>
          </friction>
        </surface>
      </collision>
      <visual name='visual'>
        <geometry>
          <sphere>
            <radius>0.25</radius>
          </sphere>
        </geometry>
        <material>
          <ambient>1 1 1 1</ambient>
          <diffuse>1 1 1 1</diffuse>
          <specular>0.1 0.1 0.1 1</specular>
          <emissive>0 0 0 0</emissive>
        </material>
      </visual>
      <velocity_decay>
        <linear>0</linear>
        <angular>0</angular>
      </velocity_decay>
    </link>
    <joint name='spring_joint_18' type='prismatic'>
      <parent>tactile_18</parent>
      <child>spring_18</child>
      <axis>
        <xyz>0 0 1</xyz>
        <limit>
          <lower>-1e+16</lower>
          <upper>1e+16</upper>
        </limit>
      </axis>
    </joint>
    <link name='tactile_18'>
      <pose>0 0.5 0.4 0 -0 0</pose>
      <inertial>
        <mass>0.001</mass>
      </inertial>
      <collision name='square_collision'>
        <geometry>
          <box>
            <size>0.5 0.5 0.01</size>
          </box>
        </geometry>
        <surface>
          <friction>
            <ode>
              <mu>0</mu>
              <mu2>0</mu2>
            </ode>
          </friction>
        </surface>
      </collision>
      <visual name='visual'>
        <geometry>
          <box>
            <size>0.5 0.5 0.01</size>
          </box>
        </geometry>
        <material>
          <ambient>1 0 0 1</ambient>
          <diffuse>1 0 0 1</diffuse>
          <specular>0.1 0.1 0.1 1</specular>
          <emissive>0 0 0 0</emissive>
        </material>
      </visual>
      <velocity_decay>
        <linear>0</linear>
        <angular>0</angular>
      </velocity_decay>
    </link>
    <joint name='tactile_joint_18' type='prismatic'>
      <parent>plane</parent>
      <child>tactile_18</child>
      <axis>
        <xyz>0 0 1</xyz>
        <limit>
          <lower>-1e+16</lower>
          <upper>1e+16</upper>
        </limit>
      </axis>
    </joint>
    <link name='spring_19'>
      <pose>0.5 0.5 1.3 0 -0 0</pose>
      <inertial>
        <mass>0.001</mass>
      </inertial>
      <collision name='sphere_collision'>
        <geometry>
          <sphere>
            <radius>0.25</radius>
          </sphere>
        </geometry>
        <surface>
          <friction>
            <ode>
              <mu>0</mu>
              <mu2>0</mu2>
            </ode>
          </friction>
        </surface>
      </collision>
      <visual name='visual'>
        <geometry>
          <sphere>
            <radius>0.25</radius>
          </sphere>
        </geometry>
        <material>
          <ambient>1 1 1 1</ambient>
          <diffuse>1 1 1 1</diffuse>
          <specular>0.1 0.1 0.1 1</specular>
          <emissive>0 0 0 0</emissive>
        </material>
      </visual>
      <velocity_decay>
        <linear>0</linear>
        <angular>0</angular>
      </velocity_decay>
    </link>
    <joint name='spring_joint_19' type='prismatic'>
      <parent>tactile_19</parent>
      <child>spring_19</child>
      <axis>
        <xyz>0 0 1</xyz>
        <limit>
          <lower>-1e+16</lower>
          <upper>1e+16</upper>
        </limit>
      </axis>
    </joint>
    <link name='tactile_19'>
      <pose>0.5 0.5 0.4 0 -0 0</pose>
      <inertial>
        <mass>0.001</mass>
      </inertial>
      <collision name='square_collision'>
        <geometry>
          <box>
            <size>0.5 0.5 0.01</size>
          </box>
        </geometry>
        <surface>
          <friction>
            <ode>
              <mu>0</mu>
              <mu2>0</mu2>
            </ode>
          </friction>
        </surface>
      </collision>
      <visual name='visual'>
        <geometry>
          <box>
            <size>0.5 0.5 0.01</size>
          </box>
        </geometry>
        <material>
          <ambient>1 0 0 1</ambient>
          <diffuse>1 0 0 1</diffuse>
          <specular>0.1 0.1 0.1 1</specular>
          <emissive>0 0 0 0</emissive>
        </material>
      </visual>
      <velocity_decay>
        <linear>0</linear>
        <angular>0</angular>
      </velocity_decay>
    </link>
    <joint name='tactile_joint_19' type='prismatic'>
      <parent>plane</parent>
      <child>tactile_19</child>
      <axis>
        <xyz>0 0 1</xyz>
        <limit>
          <lower>-1e+16</lower>
          <upper>1e+16</upper>
        </limit>
      </axis>
    </joint>
    <link name='spring_20'>
      <pose>1 0.5 1.3 0 -0 0</pose>
      <inertial>
        <mass>0.001</mass>
      </inertial>
      <collision name='sphere_collision'>
        <geometry>
          <sphere>
            <radius>0.25</radius>
          </sphere>
        </geometry>
        <surface>
          <friction>
            <ode>
              <mu>0</mu>
              <mu2>0</mu2>
            </ode>
          </friction>
        </surface>
      </collision>
      <visual name='visual'>
        <geometry>
          <sphere>
            <radius>0.25</radius>
          </sphere>
        </geometry>
        <material>
          <ambient>1 1 1 1</ambient>
          <diffuse>1 1 1 1</diffuse>
          <specular>0.1 0.1 0.1 1</specular>
          <emissive>0 0 0 0</emissive>
        </material>
      </visual>
      <velocity_decay>
        <linear>0</linear>
        <angular>0</angular>
      </velocity_decay>
    </link>
    <joint name='spring_joint_20' type='prismatic'>
      <parent>tactile_20</parent>
      <child>spring_20</child>
      <axis>
        <xyz>0 0 1</xyz>
        <limit>
          <lower>-1e+16</lower>
          <upper>1e+16</upper>
        </limit>
      </axis>
    </joint>
    <link name='tactile_20'>
      <pose>1 0.5 0.4 0 -0 0</pose>
      <inertial>
        <mass>0.001</mass>
      </inertial>
      <collision name='square_collision'>
        <geometry>
          <box>
            <size>0.5 0.5 0.01</size>
          </box>
        </geometry>
        <surface>
          <friction>
            <ode>
              <mu>0</mu>
              <mu2>0</mu2>
            </ode>
          </friction>
        </surface>
      </collision>
      <visual name='visual'>
        <geometry>
          <box>
            <size>0.5 0.5 0.01</size>
          </box>
        </geometry>
        <material>
          <ambient>1 0 0 1</ambient>
          <diffuse>1 0 0 1</diffuse>
          <specular>0.1 0.1 0.1 1</specular>
          <emissive>0 0 0 0</emissive>
        </material>
      </visual>
      <velocity_decay>
        <linear>0</linear>
        <angular>0</angular>
      </velocity_decay>
    </link>
    <joint name='tactile_joint_20' type='prismatic'>
      <parent>plane</parent>
      <child>tactile_20</child>
      <axis>
        <xyz>0 0 1</xyz>
        <limit>
          <lower>-1e+16</lower>
          <upper>1e+16</upper>
        </limit>
      </axis>
    </joint>
    <link name='spring_21'>
      <pose>1.5 0.5 1.3 0 -0 0</pose>
      <inertial>
        <mass>0.001</mass>
      </inertial>
      <collision name='sphere_collision'>
        <geometry>
          <sphere>
            <radius>0.25</radius>
          </sphere>
        </geometry>
        <surface>
          <friction>
            <ode>
              <mu>0</mu>
              <mu2>0</mu2>
            </ode>
          </friction>
        </surface>
      </collision>
      <visual name='visual'>
        <geometry>
          <sphere>
            <radius>0.25</radius>
          </sphere>
        </geometry>
        <material>
          <ambient>1 1 1 1</ambient>
          <diffuse>1 1 1 1</diffuse>
          <specular>0.1 0.1 0.1 1</specular>
          <emissive>0 0 0 0</emissive>
        </material>
      </visual>
      <velocity_decay>
        <linear>0</linear>
        <angular>0</angular>
      </velocity_decay>
    </link>
    <joint name='spring_joint_21' type='prismatic'>
      <parent>tactile_21</parent>
      <child>spring_21</child>
      <axis>
        <xyz>0 0 1</xyz>
        <limit>
          <lower>-1e+16</lower>
          <upper>1e+16</upper>
        </limit>
      </axis>
    </joint>
    <link name='tactile_21'>
      <pose>1.5 0.5 0.4 0 -0 0</pose>
      <inertial>
        <mass>0.001</mass>
      </inertial>
      <collision name='square_collision'>
        <geometry>
          <box>
            <size>0.5 0.5 0.01</size>
          </box>
        </geometry>
        <surface>
          <friction>
            <ode>
              <mu>0</mu>
              <mu2>0</mu2>
            </ode>
          </friction>
        </surface>
      </collision>
      <visual name='visual'>
        <geometry>
          <box>
            <size>0.5 0.5 0.01</size>
          </box>
        </geometry>
        <material>
          <ambient>1 0 0 1</ambient>
          <diffuse>1 0 0 1</diffuse>
          <specular>0.1 0.1 0.1 1</specular>
          <emissive>0 0 0 0</emissive>
        </material>
      </visual>
      <velocity_decay>
        <linear>0</linear>
        <angular>0</angular>
      </velocity_decay>
    </link>
    <joint name='tactile_joint_21' type='prismatic'>
      <parent>plane</parent>
      <child>tactile_21</child>
      <axis>
        <xyz>0 0 1</xyz>
        <limit>
          <lower>-1e+16</lower>
          <upper>1e+16</upper>
        </limit>
      </axis>
    </joint>
    <link name='spring_22'>
      <pose>-1.5 0 1.3 0 -0 0</pose>
      <inertial>
        <mass>0.001</mass>
      </inertial>
      <collision name='sphere_collision'>
        <geometry>
          <sphere>
            <radius>0.25</radius>
          </sphere>
        </geometry>
        <surface>
          <friction>
            <ode>
              <mu>0</mu>
              <mu2>0</mu2>
            </ode>
          </friction>
        </surface>
      </collision>
      <visual name='visual'>
        <geometry>
          <sphere>
            <radius>0.25</radius>
          </sphere>
        </geometry>
        <material>
          <ambient>1 1 1 1</ambient>
          <diffuse>1 1 1 1</diffuse>
          <specular>0.1 0.1 0.1 1</specular>
          <emissive>0 0 0 0</emissive>
        </material>
      </visual>
      <velocity_decay>
        <linear>0</linear>
        <angular>0</angular>
      </velocity_decay>
    </link>
    <joint name='spring_joint_22' type='prismatic'>
      <parent>tactile_22</parent>
      <child>spring_22</child>
      <axis>
        <xyz>0 0 1</xyz>
        <limit>
          <lower>-1e+16</lower>
          <upper>1e+16</upper>
        </limit>
      </axis>
    </joint>
    <link name='tactile_22'>
      <pose>-1.5 0 0.4 0 -0 0</pose>
      <inertial>
        <mass>0.001</mass>
      </inertial>
      <collision name='square_collision'>
        <geometry>
          <box>
            <size>0.5 0.5 0.01</size>
          </box>
        </geometry>
        <surface>
          <friction>
            <ode>
              <mu>0</mu>
              <mu2>0</mu2>
            </ode>
          </friction>
        </surface>
      </collision>
      <visual name='visual'>
        <geometry>
          <box>
            <size>0.5 0.5 0.01</size>
          </box>
        </geometry>
        <material>
          <ambient>1 0 0 1</ambient>
          <diffuse>1 0 0 1</diffuse>
          <specular>0.1 0.1 0.1 1</specular>
          <emissive>0 0 0 0</emissive>
        </material>
      </visual>
      <velocity_decay>
        <linear>0</linear>
        <angular>0</angular>
      </velocity_decay>
    </link>
    <joint name='tactile_joint_22' type='prismatic'>
      <parent>plane</parent>
      <child>tactile_22</child>
      <axis>
        <xyz>0 0 1</xyz>
        <limit>
          <lower>-1e+16</lower>
          <upper>1e+16</upper>
        </limit>
      </axis>
    </joint>
    <link name='spring_23'>
      <pose>-1 0 1.3 0 -0 0</pose>
      <inertial>
        <mass>0.001</mass>
      </inertial>
      <collision name='sphere_collision'>
        <geometry>
          <sphere>
            <radius>0.25</radius>
          </sphere>
        </geometry>
        <surface>
          <friction>
            <ode>
              <mu>0</mu>
              <mu2>0</mu2>
            </ode>
          </friction>
        </surface>
      </collision>
      <visual name='visual'>
        <geometry>
          <sphere>
            <radius>0.25</radius>
          </sphere>
        </geometry>
        <material>
          <ambient>1 1 1 1</ambient>
          <diffuse>1 1 1 1</diffuse>
          <specular>0.1 0.1 0.1 1</specular>
          <emissive>0 0 0 0</emissive>
        </material>
      </visual>
      <velocity_decay>
        <linear>0</linear>
        <angular>0</angular>
      </velocity_decay>
    </link>
    <joint name='spring_joint_23' type='prismatic'>
      <parent>tactile_23</parent>
      <child>spring_23</child>
      <axis>
        <xyz>0 0 1</xyz>
        <limit>
          <lower>-1e+16</lower>
          <upper>1e+16</upper>
        </limit>
      </axis>
    </joint>
    <link name='tactile_23'>
      <pose>-1 0 0.4 0 -0 0</pose>
      <inertial>
        <mass>0.001</mass>
      </inertial>
      <collision name='square_collision'>
        <geometry>
          <box>
            <size>0.5 0.5 0.01</size>
          </box>
        </geometry>
        <surface>
          <friction>
            <ode>
              <mu>0</mu>
              <mu2>0</mu2>
            </ode>
          </friction>
        </surface>
      </collision>
      <visual name='visual'>
        <geometry>
          <box>
            <size>0.5 0.5 0.01</size>
          </box>
        </geometry>
        <material>
          <ambient>1 0 0 1</ambient>
          <diffuse>1 0 0 1</diffuse>
          <specular>0.1 0.1 0.1 1</specular>
          <emissive>0 0 0 0</emissive>
        </material>
      </visual>
      <velocity_decay>
        <linear>0</linear>
        <angular>0</angular>
      </velocity_decay>
    </link>
    <joint name='tactile_joint_23' type='prismatic'>
      <parent>plane</parent>
      <child>tactile_23</child>
      <axis>
        <xyz>0 0 1</xyz>
        <limit>
          <lower>-1e+16</lower>
          <upper>1e+16</upper>
        </limit>
      </axis>
    </joint>
    <link name='spring_24'>
      <pose>-0.5 0 1.3 0 -0 0</pose>
      <inertial>
        <mass>0.001</mass>
      </inertial>
      <collision name='sphere_collision'>
        <geometry>
          <sphere>
            <radius>0.25</radius>
          </sphere>
        </geometry>
        <surface>
          <friction>
            <ode>
              <mu>0</mu>
              <mu2>0</mu2>
            </ode>
          </friction>
        </surface>
      </collision>
      <visual name='visual'>
        <geometry>
          <sphere>
            <radius>0.25</radius>
          </sphere>
        </geometry>
        <material>
          <ambient>1 1 1 1</ambient>
          <diffuse>1 1 1 1</diffuse>
          <specular>0.1 0.1 0.1 1</specular>
          <emissive>0 0 0 0</emissive>
        </material>
      </visual>
      <velocity_decay>
        <linear>0</linear>
        <angular>0</angular>
      </velocity_decay>
    </link>
    <joint name='spring_joint_24' type='prismatic'>
      <parent>tactile_24</parent>
      <child>spring_24</child>
      <axis>
        <xyz>0 0 1</xyz>
        <limit>
          <lower>-1e+16</lower>
          <upper>1e+16</upper>
        </limit>
      </axis>
    </joint>
    <link name='tactile_24'>
      <pose>-0.5 0 0.4 0 -0 0</pose>
      <inertial>
        <mass>0.001</mass>
      </inertial>
      <collision name='square_collision'>
        <geometry>
          <box>
            <size>0.5 0.5 0.01</size>
          </box>
        </geometry>
        <surface>
          <friction>
            <ode>
              <mu>0</mu>
              <mu2>0</mu2>
            </ode>
          </friction>
        </surface>
      </collision>
      <visual name='visual'>
        <geometry>
          <box>
            <size>0.5 0.5 0.01</size>
          </box>
        </geometry>
        <material>
          <ambient>1 0 0 1</ambient>
          <diffuse>1 0 0 1</diffuse>
          <specular>0.1 0.1 0.1 1</specular>
          <emissive>0 0 0 0</emissive>
        </material>
      </visual>
      <velocity_decay>
        <linear>0</linear>
        <angular>0</angular>
      </velocity_decay>
    </link>
    <joint name='tactile_joint_24' type='prismatic'>
      <parent>plane</parent>
      <child>tactile_24</child>
      <axis>
        <xyz>0 0 1</xyz>
        <limit>
          <lower>-1e+16</lower>
          <upper>1e+16</upper>
        </limit>
      </axis>
    </joint>
    <link name='spring_25'>
      <pose>0 0 1.3 0 -0 0</pose>
      <inertial>
        <mass>0.001</mass>
      </inertial>
      <collision name='sphere_collision'>
        <geometry>
          <sphere>
            <radius>0.25</radius>
          </sphere>
        </geometry>
        <surface>
          <friction>
            <ode>
              <mu>0</mu>
              <mu2>0</mu2>
            </ode>
          </friction>
        </surface>
      </collision>
      <visual name='visual'>
        <geometry>
          <sphere>
            <radius>0.25</radius>
          </sphere>
        </geometry>
        <material>
          <ambient>1 1 1 1</ambient>
          <diffuse>1 1 1 1</diffuse>
          <specular>0.1 0.1 0.1 1</specular>
          <emissive>0 0 0 0</emissive>
        </material>
      </visual>
      <velocity_decay>
        <linear>0</linear>
        <angular>0</angular>
      </velocity_decay>
    </link>
    <joint name='spring_joint_25' type='prismatic'>
      <parent>tactile_25</parent>
      <child>spring_25</child>
      <axis>
        <xyz>0 0 1</xyz>
        <limit>
          <lower>-1e+16</lower>
          <upper>1e+16</upper>
        </limit>
      </axis>
    </joint>
    <link name='tactile_25'>
      <pose>0 0 0.4 0 -0 0</pose>
      <inertial>
        <mass>0.001</mass>
      </inertial>
      <collision name='square_collision'>
        <geometry>
          <box>
            <size>0.5 0.5 0.01</size>
          </box>
        </geometry>
        <surface>
          <friction>
            <ode>
              <mu>0</mu>
              <mu2>0</mu2>
            </ode>
          </friction>
        </surface>
      </collision>
      <visual name='visual'>
        <geometry>
          <box>
            <size>0.5 0.5 0.01</size>
          </box>
        </geometry>
        <material>
          <ambient>1 0 0 1</ambient>
          <diffuse>1 0 0 1</diffuse>
          <specular>0.1 0.1 0.1 1</specular>
          <emissive>0 0 0 0</emissive>
        </material>
      </visual>
      <velocity_decay>
        <linear>0</linear>
        <angular>0</angular>
      </velocity_decay>
    </link>
    <joint name='tactile_joint_25' type='prismatic'>
      <parent>plane</parent>
      <child>tactile_25</child>
      <axis>
        <xyz>0 0 1</xyz>
        <limit>
          <lower>-1e+16</lower>
          <upper>1e+16</upper>
        </limit>
      </axis>
    </joint>
    <link name='spring_26'>
      <pose>0.5 0 1.3 0 -0 0</pose>
      <inertial>
        <mass>0.001</mass>
      </inertial>
      <collision name='sphere_collision'>
        <geometry>
          <sphere>
            <radius>0.25</radius>
          </sphere>
        </geometry>
        <surface>
          <friction>
            <ode>
              <mu>0</mu>
              <mu2>0</mu2>
            </ode>
          </friction>
        </surface>
      </collision>
      <visual name='visual'>
        <geometry>
          <sphere>
            <radius>0.25</radius>
          </sphere>
        </geometry>
        <material>
          <ambient>1 1 1 1</ambient>
          <diffuse>1 1 1 1</diffuse>
          <specular>0.1 0.1 0.1 1</specular>
          <emissive>0 0 0 0</emissive>
        </material>
      </visual>
      <velocity_decay>
        <linear>0</linear>
        <angular>0</angular>
      </velocity_decay>
    </link>
    <joint name='spring_joint_26' type='prismatic'>
      <parent>tactile_26</parent>
      <child>spring_26</child>
      <axis>
        <xyz>0 0 1</xyz>
        <limit>
          <lower>-1e+16</lower>
          <upper>1e+16</upper>
        </limit>
      </axis>
    </joint>
    <link name='tactile_26'>
      <pose>0.5 0 0.4 0 -0 0</pose>
      <inertial>
        <mass>0.001</mass>
      </inertial>
      <collision name='square_collision'>
        <geometry>
          <box>
            <size>0.5 0.5 0.01</size>
          </box>
        </geometry>
        <surface>
          <friction>
            <ode>
              <mu>0</mu>
              <mu2>0</mu2>
            </ode>
          </friction>
        </surface>
      </collision>
      <visual name='visual'>
        <geometry>
          <box>
            <size>0.5 0.5 0.01</size>
          </box>
        </geometry>
        <material>
          <ambient>1 0 0 1</ambient>
          <diffuse>1 0 0 1</diffuse>
          <specular>0.1 0.1 0.1 1</specular>
          <emissive>0 0 0 0</emissive>
        </material>
      </visual>
      <velocity_decay>
        <linear>0</linear>
        <angular>0</angular>
      </velocity_decay>
    </link>
    <joint name='tactile_joint_26' type='prismatic'>
      <parent>plane</parent>
      <child>tactile_26</child>
      <axis>
        <xyz>0 0 1</xyz>
        <limit>
          <lower>-1e+16</lower>
          <upper>1e+16</upper>
        </limit>
      </axis>
    </joint>
    <link name='spring_27'>
      <pose>1 0 1.3 0 -0 0</pose>
      <inertial>
        <mass>0.001</mass>
      </inertial>
      <collision name='sphere_collision'>
        <geometry>
          <sphere>
            <radius>0.25</radius>
          </sphere>
        </geometry>
        <surface>
          <friction>
            <ode>
              <mu>0</mu>
              <mu2>0</mu2>
            </ode>
          </friction>
        </surface>
      </collision>
      <visual name='visual'>
        <geometry>
          <sphere>
            <radius>0.25</radius>
          </sphere>
        </geometry>
        <material>
          <ambient>1 1 1 1</ambient>
          <diffuse>1 1 1 1</diffuse>
          <specular>0.1 0.1 0.1 1</specular>
          <emissive>0 0 0 0</emissive>
        </material>
      </visual>
      <velocity_decay>
        <linear>0</linear>
        <angular>0</angular>
      </velocity_decay>
    </link>
    <joint name='spring_joint_27' type='prismatic'>
      <parent>tactile_27</parent>
      <child>spring_27</child>
      <axis>
        <xyz>0 0 1</xyz>
        <limit>
          <lower>-1e+16</lower>
          <upper>1e+16</upper>
        </limit>
      </axis>
    </joint>
    <link name='tactile_27'>
      <pose>1 0 0.4 0 -0 0</pose>
      <inertial>
        <mass>0.001</mass>
      </inertial>
      <collision name='square_collision'>
        <geometry>
          <box>
            <size>0.5 0.5 0.01</size>
          </box>
        </geometry>
        <surface>
          <friction>
            <ode>
              <mu>0</mu>
              <mu2>0</mu2>
            </ode>
          </friction>
        </surface>
      </collision>
      <visual name='visual'>
        <geometry>
          <box>
            <size>0.5 0.5 0.01</size>
          </box>
        </geometry>
        <material>
          <ambient>1 0 0 1</ambient>
          <diffuse>1 0 0 1</diffuse>
          <specular>0.1 0.1 0.1 1</specular>
          <emissive>0 0 0 0</emissive>
        </material>
      </visual>
      <velocity_decay>
        <linear>0</linear>
        <angular>0</angular>
      </velocity_decay>
    </link>
    <joint name='tactile_joint_27' type='prismatic'>
      <parent>plane</parent>
      <child>tactile_27</child>
      <axis>
        <xyz>0 0 1</xyz>
        <limit>
          <lower>-1e+16</lower>
          <upper>1e+16</upper>
        </limit>
      </axis>
    </joint>
    <link name='spring_28'>
      <pose>1.5 0 1.3 0 -0 0</pose>
      <inertial>
        <mass>0.001</mass>
      </inertial>
      <collision name='sphere_collision'>
        <geometry>
          <sphere>
            <radius>0.25</radius>
          </sphere>
        </geometry>
        <surface>
          <friction>
            <ode>
              <mu>0</mu>
              <mu2>0</mu2>
            </ode>
          </friction>
        </surface>
      </collision>
      <visual name='visual'>
        <geometry>
          <sphere>
            <radius>0.25</radius>
          </sphere>
        </geometry>
        <material>
          <ambient>1 1 1 1</ambient>
          <diffuse>1 1 1 1</diffuse>
          <specular>0.1 0.1 0.1 1</specular>
          <emissive>0 0 0 0</emissive>
        </material>
      </visual>
      <velocity_decay>
        <linear>0</linear>
        <angular>0</angular>
      </velocity_decay>
    </link>
    <joint name='spring_joint_28' type='prismatic'>
      <parent>tactile_28</parent>
      <child>spring_28</child>
      <axis>
        <xyz>0 0 1</xyz>
        <limit>
          <lower>-1e+16</lower>
          <upper>1e+16</upper>
        </limit>
      </axis>
    </joint>
    <link name='tactile_28'>
      <pose>1.5 0 0.4 0 -0 0</pose>
      <inertial>
        <mass>0.001</mass>
      </inertial>
      <collision name='square_collision'>
        <geometry>
          <box>
            <size>0.5 0.5 0.01</size>
          </box>
        </geometry>
        <surface>
          <friction>
            <ode>
              <mu>0</mu>
              <mu2>0</mu2>
            </ode>
          </friction>
        </surface>
      </collision>
      <visual name='visual'>
        <geometry>
          <box>
            <size>0.5 0.5 0.01</size>
          </box>
        </geometry>
        <material>
          <ambient>1 0 0 1</ambient>
          <diffuse>1 0 0 1</diffuse>
          <specular>0.1 0.1 0.1 1</specular>
          <emissive>0 0 0 0</emissive>
        </material>
      </visual>
      <velocity_decay>
        <linear>0</linear>
        <angular>0</angular>
      </velocity_decay>
    </link>
    <joint name='tactile_joint_28' type='prismatic'>
      <parent>plane</parent>
      <child>tactile_28</child>
      <axis>
        <xyz>0 0 1</xyz>
        <limit>
          <lower>-1e+16</lower>
          <upper>1e+16</upper>
        </limit>
      </axis>
    </joint>
    <link name='spring_29'>
      <pose>-1.5 -0.5 1.3 0 -0 0</pose>
      <inertial>
        <mass>0.001</mass>
      </inertial>
      <collision name='sphere_collision'>
        <geometry>
          <sphere>
            <radius>0.25</radius>
          </sphere>
        </geometry>
        <surface>
          <friction>
            <ode>
              <mu>0</mu>
              <mu2>0</mu2>
            </ode>
          </friction>
        </surface>
      </collision>
      <visual name='visual'>
        <geometry>
          <sphere>
            <radius>0.25</radius>
          </sphere>
        </geometry>
        <material>
          <ambient>1 1 1 1</ambient>
          <diffuse>1 1 1 1</diffuse>
          <specular>0.1 0.1 0.1 1</specular>
          <emissive>0 0 0 0</emissive>
        </material>
      </visual>
      <velocity_decay>
        <linear>0</linear>
        <angular>0</angular>
      </velocity_decay>
    </link>
    <joint name='spring_joint_29' type='prismatic'>
      <parent>tactile_29</parent>
      <child>spring_29</child>
      <axis>
        <xyz>0 0 1</xyz>
        <limit>
          <lower>-1e+16</lower>
          <upper>1e+16</upper>
        </limit>
      </axis>
    </joint>
    <link name='tactile_29'>
      <pose>-1.5 -0.5 0.4 0 -0 0</pose>
      <inertial>
        <mass>0.001</mass>
      </inertial>
      <collision name='square_collision'>
        <geometry>
          <box>
            <size>0.5 0.5 0.01</size>
          </box>
        </geometry>
        <surface>
          <friction>
            <ode>
              <mu>0</mu>
              <mu2>0</mu2>
            </ode>
          </friction>
        </surface>
      </collision>
      <visual name='visual'>
        <geometry>
          <box>
            <size>0.5 0.5 0.01</size>
          </box>
        </geometry>
        <material>
          <ambient>1 0 0 1</ambient>
          <diffuse>1 0 0 1</diffuse>
          <specular>0.1 0.1 0.1 1</specular>
          <emissive>0 0 0 0</emissive>
        </material>
      </visual>
      <velocity_decay>
        <linear>0</linear>
        <angular>0</angular>
      </velocity_decay>
    </link>
    <joint name='tactile_joint_29' type='prismatic'>
      <parent>plane</parent>
      <child>tactile_29</child>
      <axis>
        <xyz>0 0 1</xyz>
        <limit>
          <lower>-1e+16</lower>
          <upper>1e+16</upper>
        </limit>
      </axis>
    </joint>
    <link name='spring_30'>
      <pose>-1 -0.5 1.3 0 -0 0</pose>
      <inertial>
        <mass>0.001</mass>
      </inertial>
      <collision name='sphere_collision'>
        <geometry>
          <sphere>
            <radius>0.25</radius>
          </sphere>
        </geometry>
        <surface>
          <friction>
            <ode>
              <mu>0</mu>
              <mu2>0</mu2>
            </ode>
          </friction>
        </surface>
      </collision>
      <visual name='visual'>
        <geometry>
          <sphere>
            <radius>0.25</radius>
          </sphere>
        </geometry>
        <material>
          <ambient>1 1 1 1</ambient>
          <diffuse>1 1 1 1</diffuse>
          <specular>0.1 0.1 0.1 1</specular>
          <emissive>0 0 0 0</emissive>
        </material>
      </visual>
      <velocity_decay>
        <linear>0</linear>
        <angular>0</angular>
      </velocity_decay>
    </link>
    <joint name='spring_joint_30' type='prismatic'>
      <parent>tactile_30</parent>
      <child>spring_30</child>
      <axis>
        <xyz>0 0 1</xyz>
        <limit>
          <lower>-1e+16</lower>
          <upper>1e+16</upper>
        </limit>
      </axis>
    </joint>
    <link name='tactile_30'>
      <pose>-1 -0.5 0.4 0 -0 0</pose>
      <inertial>
        <mass>0.001</mass>
      </inertial>
      <collision name='square_collision'>
        <geometry>
          <box>
            <size>0.5 0.5 0.01</size>
          </box>
        </geometry>
        <surface>
          <friction>
            <ode>
              <mu>0</mu>
              <mu2>0</mu2>
            </ode>
          </friction>
        </surface>
      </collision>
      <visual name='visual'>
        <geometry>
          <box>
            <size>0.5 0.5 0.01</size>
          </box>
        </geometry>
        <material>
          <ambient>1 0 0 1</ambient>
          <diffuse>1 0 0 1</diffuse>
          <specular>0.1 0.1 0.1 1</specular>
          <emissive>0 0 0 0</emissive>
        </material>
      </visual>
      <velocity_decay>
        <linear>0</linear>
        <angular>0</angular>
      </velocity_decay>
    </link>
    <joint name='tactile_joint_30' type='prismatic'>
      <parent>plane</parent>
      <child>tactile_30</child>
      <axis>
        <xyz>0 0 1</xyz>
        <limit>
          <lower>-1e+16</lower>
          <upper>1e+16</upper>
        </limit>
      </axis>
    </joint>
    <link name='spring_31'>
      <pose>-0.5 -0.5 1.3 0 -0 0</pose>
      <inertial>
        <mass>0.001</mass>
      </inertial>
      <collision name='sphere_collision'>
        <geometry>
          <sphere>
            <radius>0.25</radius>
          </sphere>
        </geometry>
        <surface>
          <friction>
            <ode>
              <mu>0</mu>
              <mu2>0</mu2>
            </ode>
          </friction>
        </surface>
      </collision>
      <visual name='visual'>
        <geometry>
          <sphere>
            <radius>0.25</radius>
          </sphere>
        </geometry>
        <material>
          <ambient>1 1 1 1</ambient>
          <diffuse>1 1 1 1</diffuse>
          <specular>0.1 0.1 0.1 1</specular>
          <emissive>0 0 0 0</emissive>
        </material>
      </visual>
      <velocity_decay>
        <linear>0</linear>
        <angular>0</angular>
      </velocity_decay>
    </link>
    <joint name='spring_joint_31' type='prismatic'>
      <parent>tactile_31</parent>
      <child>spring_31</child>
      <axis>
        <xyz>0 0 1</xyz>
        <limit>
          <lower>-1e+16</lower>
          <upper>1e+16</upper>
        </limit>
      </axis>
    </joint>
    <link name='tactile_31'>
      <pose>-0.5 -0.5 0.4 0 -0 0</pose>
      <inertial>
        <mass>0.001</mass>
      </inertial>
      <collision name='square_collision'>
        <geometry>
          <box>
            <size>0.5 0.5 0.01</size>
          </box>
        </geometry>
        <surface>
          <friction>
            <ode>
              <mu>0</mu>
              <mu2>0</mu2>
            </ode>
          </friction>
        </surface>
      </collision>
      <visual name='visual'>
        <geometry>
          <box>
            <size>0.5 0.5 0.01</size>
          </box>
        </geometry>
        <material>
          <ambient>1 0 0 1</ambient>
          <diffuse>1 0 0 1</diffuse>
          <specular>0.1 0.1 0.1 1</specular>
          <emissive>0 0 0 0</emissive>
        </material>
      </visual>
      <velocity_decay>
        <linear>0</linear>
        <angular>0</angular>
      </velocity_decay>
    </link>
    <joint name='tactile_joint_31' type='prismatic'>
      <parent>plane</parent>
      <child>tactile_31</child>
      <axis>
        <xyz>0 0 1</xyz>
        <limit>
          <lower>-1e+16</lower>
          <upper>1e+16</upper>
        </limit>
      </axis>
    </joint>
    <link name='spring_32'>
      <pose>0 -0.5 1.3 0 -0 0</pose>
      <inertial>
        <mass>0.001</mass>
      </inertial>
      <collision name='sphere_collision'>
        <geometry>
          <sphere>
            <radius>0.25</radius>
          </sphere>
        </geometry>
        <surface>
          <friction>
            <ode>
              <mu>0</mu>
              <mu2>0</mu2>
            </ode>
          </friction>
        </surface>
      </collision>
      <visual name='visual'>
        <geometry>
          <sphere>
            <radius>0.25</radius>
          </sphere>
        </geometry>
        <material>
          <ambient>1 1 1 1</ambient>
          <diffuse>1 1 1 1</diffuse>
          <specular>0.1 0.1 0.1 1</specular>
          <emissive>0 0 0 0</emissive>
        </material>
      </visual>
      <velocity_decay>
        <linear>0</linear>
        <angular>0</angular>
      </velocity_decay>
    </link>
    <joint name='spring_joint_32' type='prismatic'>
      <parent>tactile_32</parent>
      <child>spring_32</child>
      <axis>
        <xyz>0 0 1</xyz>
        <limit>
          <lower>-1e+16</lower>
          <upper>1e+16</upper>
        </limit>
      </axis>
    </joint>
    <link name='tactile_32'>
      <pose>0 -0.5 0.4 0 -0 0</pose>
      <inertial>
        <mass>0.001</mass>
      </inertial>
      <collision name='square_collision'>
        <geometry>
          <box>
            <size>0.5 0.5 0.01</size>
          </box>
        </geometry>
        <surface>
          <friction>
            <ode>
              <mu>0</mu>
              <mu2>0</mu2>
            </ode>
          </friction>
        </surface>
      </collision>
      <visual name='visual'>
        <geometry>
          <box>
            <size>0.5 0.5 0.01</size>
          </box>
        </geometry>
        <material>
          <ambient>1 0 0 1</ambient>
          <diffuse>1 0 0 1</diffuse>
          <specular>0.1 0.1 0.1 1</specular>
          <emissive>0 0 0 0</emissive>
        </material>
      </visual>
      <velocity_decay>
        <linear>0</linear>
        <angular>0</angular>
      </velocity_decay>
    </link>
    <joint name='tactile_joint_32' type='prismatic'>
      <parent>plane</parent>
      <child>tactile_32</child>
      <axis>
        <xyz>0 0 1</xyz>
        <limit>
          <lower>-1e+16</lower>
          <upper>1e+16</upper>
        </limit>
      </axis>
    </joint>
    <link name='spring_33'>
      <pose>0.5 -0.5 1.3 0 -0 0</pose>
      <inertial>
        <mass>0.001</mass>
      </inertial>
      <collision name='sphere_collision'>
        <geometry>
          <sphere>
            <radius>0.25</radius>
          </sphere>
        </geometry>
        <surface>
          <friction>
            <ode>
              <mu>0</mu>
              <mu2>0</mu2>
            </ode>
          </friction>
        </surface>
      </collision>
      <visual name='visual'>
        <geometry>
          <sphere>
            <radius>0.25</radius>
          </sphere>
        </geometry>
        <material>
          <ambient>1 1 1 1</ambient>
          <diffuse>1 1 1 1</diffuse>
          <specular>0.1 0.1 0.1 1</specular>
          <emissive>0 0 0 0</emissive>
        </material>
      </visual>
      <velocity_decay>
        <linear>0</linear>
        <angular>0</angular>
      </velocity_decay>
    </link>
    <joint name='spring_joint_33' type='prismatic'>
      <parent>tactile_33</parent>
      <child>spring_33</child>
      <axis>
        <xyz>0 0 1</xyz>
        <limit>
          <lower>-1e+16</lower>
          <upper>1e+16</upper>
        </limit>
      </axis>
    </joint>
    <link name='tactile_33'>
      <pose>0.5 -0.5 0.4 0 -0 0</pose>
      <inertial>
        <mass>0.001</mass>
      </inertial>
      <collision name='square_collision'>
        <geometry>
          <box>
            <size>0.5 0.5 0.01</size>
          </box>
        </geometry>
        <surface>
          <friction>
            <ode>
              <mu>0</mu>
              <mu2>0</mu2>
            </ode>
          </friction>
        </surface>
      </collision>
      <visual name='visual'>
        <geometry>
          <box>
            <size>0.5 0.5 0.01</size>
          </box>
        </geometry>
        <material>
          <ambient>1 0 0 1</ambient>
          <diffuse>1 0 0 1</diffuse>
          <specular>0.1 0.1 0.1 1</specular>
          <emissive>0 0 0 0</emissive>
        </material>
      </visual>
      <velocity_decay>
        <linear>0</linear>
        <angular>0</angular>
      </velocity_decay>
    </link>
    <joint name='tactile_joint_33' type='prismatic'>
      <parent>plane</parent>
      <child>tactile_33</child>
      <axis>
        <xyz>0 0 1</xyz>
        <limit>
          <lower>-1e+16</lower>
          <upper>1e+16</upper>
        </limit>
      </axis>
    </joint>
    <link name='spring_34'>
      <pose>1 -0.5 1.3 0 -0 0</pose>
      <inertial>
        <mass>0.001</mass>
      </inertial>
      <collision name='sphere_collision'>
        <geometry>
          <sphere>
            <radius>0.25</radius>
          </sphere>
        </geometry>
        <surface>
          <friction>
            <ode>
              <mu>0</mu>
              <mu2>0</mu2>
            </ode>
          </friction>
        </surface>
      </collision>
      <visual name='visual'>
        <geometry>
          <sphere>
            <radius>0.25</radius>
          </sphere>
        </geometry>
        <material>
          <ambient>1 1 1 1</ambient>
          <diffuse>1 1 1 1</diffuse>
          <specular>0.1 0.1 0.1 1</specular>
          <emissive>0 0 0 0</emissive>
        </material>
      </visual>
      <velocity_decay>
        <linear>0</linear>
        <angular>0</angular>
      </velocity_decay>
    </link>
    <joint name='spring_joint_34' type='prismatic'>
      <parent>tactile_34</parent>
      <child>spring_34</child>
      <axis>
        <xyz>0 0 1</xyz>
        <limit>
          <lower>-1e+16</lower>
          <upper>1e+16</upper>
        </limit>
      </axis>
    </joint>
    <link name='tactile_34'>
      <pose>1 -0.5 0.4 0 -0 0</pose>
      <inertial>
        <mass>0.001</mass>
      </inertial>
      <collision name='square_collision'>
        <geometry>
          <box>
            <size>0.5 0.5 0.01</size>
          </box>
        </geometry>
        <surface>
          <friction>
            <ode>
              <mu>0</mu>
              <mu2>0</mu2>
            </ode>
          </friction>
        </surface>
      </collision>
      <visual name='visual'>
        <geometry>
          <box>
            <size>0.5 0.5 0.01</size>
          </box>
        </geometry>
        <material>
          <ambient>1 0 0 1</ambient>
          <diffuse>1 0 0 1</diffuse>
          <specular>0.1 0.1 0.1 1</specular>
          <emissive>0 0 0 0</emissive>
        </material>
      </visual>
      <velocity_decay>
        <linear>0</linear>
        <angular>0</angular>
      </velocity_decay>
    </link>
    <joint name='tactile_joint_34' type='prismatic'>
      <parent>plane</parent>
      <child>tactile_34</child>
      <axis>
        <xyz>0 0 1</xyz>
        <limit>
          <lower>-1e+16</lower>
          <upper>1e+16</upper>
        </limit>
      </axis>
    </joint>
    <link name='spring_35'>
      <pose>1.5 -0.5 1.3 0 -0 0</pose>
      <inertial>
        <mass>0.001</mass>
      </inertial>
      <collision name='sphere_collision'>
        <geometry>
          <sphere>
            <radius>0.25</radius>
          </sphere>
        </geometry>
        <surface>
          <friction>
            <ode>
              <mu>0</mu>
              <mu2>0</mu2>
            </ode>
          </friction>
        </surface>
      </collision>
      <visual name='visual'>
        <geometry>
          <sphere>
            <radius>0.25</radius>
          </sphere>
        </geometry>
        <material>
          <ambient>1 1 1 1</ambient>
          <diffuse>1 1 1 1</diffuse>
          <specular>0.1 0.1 0.1 1</specular>
          <emissive>0 0 0 0</emissive>
        </material>
      </visual>
      <velocity_decay>
        <linear>0</linear>
        <angular>0</angular>
      </velocity_decay>
    </link>
    <joint name='spring_joint_35' type='prismatic'>
      <parent>tactile_35</parent>
      <child>spring_35</child>
      <axis>
        <xyz>0 0 1</xyz>
        <limit>
          <lower>-1e+16</lower>
          <upper>1e+16</upper>
        </limit>
      </axis>
    </joint>
    <link name='tactile_35'>
      <pose>1.5 -0.5 0.4 0 -0 0</pose>
      <inertial>
        <mass>0.001</mass>
      </inertial>
      <collision name='square_collision'>
        <geometry>
          <box>
            <size>0.5 0.5 0.01</size>
          </box>
        </geometry>
        <surface>
          <friction>
            <ode>
              <mu>0</mu>
              <mu2>0</mu2>
            </ode>
          </friction>
        </surface>
      </collision>
      <visual name='visual'>
        <geometry>
          <box>
            <size>0.5 0.5 0.01</size>
          </box>
        </geometry>
        <material>
          <ambient>1 0 0 1</ambient>
          <diffuse>1 0 0 1</diffuse>
          <specular>0.1 0.1 0.1 1</specular>
          <emissive>0 0 0 0</emissive>
        </material>
      </visual>
      <velocity_decay>
        <linear>0</linear>
        <angular>0</angular>
      </velocity_decay>
    </link>
    <joint name='tactile_joint_35' type='prismatic'>
      <parent>plane</parent>
      <child>tactile_35</child>
      <axis>
        <xyz>0 0 1</xyz>
        <limit>
          <lower>-1e+16</lower>
          <upper>1e+16</upper>
        </limit>
      </axis>
    </joint>
    <link name='spring_36'>
      <pose>-1.5 -1 1.3 0 -0 0</pose>
      <inertial>
        <mass>0.001</mass>
      </inertial>
      <collision name='sphere_collision'>
        <geometry>
          <sphere>
            <radius>0.25</radius>
          </sphere>
        </geometry>
        <surface>
          <friction>
            <ode>
              <mu>0</mu>
              <mu2>0</mu2>
            </ode>
          </friction>
        </surface>
      </collision>
      <visual name='visual'>
        <geometry>
          <sphere>
            <radius>0.25</radius>
          </sphere>
        </geometry>
        <material>
          <ambient>1 1 1 1</ambient>
          <diffuse>1 1 1 1</diffuse>
          <specular>0.1 0.1 0.1 1</specular>
          <emissive>0 0 0 0</emissive>
        </material>
      </visual>
      <velocity_decay>
        <linear>0</linear>
        <angular>0</angular>
      </velocity_decay>
    </link>
    <joint name='spring_joint_36' type='prismatic'>
      <parent>tactile_36</parent>
      <child>spring_36</child>
      <axis>
        <xyz>0 0 1</xyz>
        <limit>
          <lower>-1e+16</lower>
          <upper>1e+16</upper>
        </limit>
      </axis>
    </joint>
    <link name='tactile_36'>
      <pose>-1.5 -1 0.4 0 -0 0</pose>
      <inertial>
        <mass>0.001</mass>
      </inertial>
      <collision name='square_collision'>
        <geometry>
          <box>
            <size>0.5 0.5 0.01</size>
          </box>
        </geometry>
        <surface>
          <friction>
            <ode>
              <mu>0</mu>
              <mu2>0</mu2>
            </ode>
          </friction>
        </surface>
      </collision>
      <visual name='visual'>
        <geometry>
          <box>
            <size>0.5 0.5 0.01</size>
          </box>
        </geometry>
        <material>
          <ambient>1 0 0 1</ambient>
          <diffuse>1 0 0 1</diffuse>
          <specular>0.1 0.1 0.1 1</specular>
          <emissive>0 0 0 0</emissive>
        </material>
      </visual>
      <velocity_decay>
        <linear>0</linear>
        <angular>0</angular>
      </velocity_decay>
    </link>
    <joint name='tactile_joint_36' type='prismatic'>
      <parent>plane</parent>
      <child>tactile_36</child>
      <axis>
        <xyz>0 0 1</xyz>
        <limit>
          <lower>-1e+16</lower>
          <upper>1e+16</upper>
        </limit>
      </axis>
    </joint>
    <link name='spring_37'>
      <pose>-1 -1 1.3 0 -0 0</pose>
      <inertial>
        <mass>0.001</mass>
      </inertial>
      <collision name='sphere_collision'>
        <geometry>
          <sphere>
            <radius>0.25</radius>
          </sphere>
        </geometry>
        <surface>
          <friction>
            <ode>
              <mu>0</mu>
              <mu2>0</mu2>
            </ode>
          </friction>
        </surface>
      </collision>
      <visual name='visual'>
        <geometry>
          <sphere>
            <radius>0.25</radius>
          </sphere>
        </geometry>
        <material>
          <ambient>1 1 1 1</ambient>
          <diffuse>1 1 1 1</diffuse>
          <specular>0.1 0.1 0.1 1</specular>
          <emissive>0 0 0 0</emissive>
        </material>
      </visual>
      <velocity_decay>
        <linear>0</linear>
        <angular>0</angular>
      </velocity_decay>
    </link>
    <joint name='spring_joint_37' type='prismatic'>
      <parent>tactile_37</parent>
      <child>spring_37</child>
      <axis>
        <xyz>0 0 1</xyz>
        <limit>
          <lower>-1e+16</lower>
          <upper>1e+16</upper>
        </limit>
      </axis>
    </joint>
    <link name='tactile_37'>
      <pose>-1 -1 0.4 0 -0 0</pose>
      <inertial>
        <mass>0.001</mass>
      </inertial>
      <collision name='square_collision'>
        <geometry>
          <box>
            <size>0.5 0.5 0.01</size>
          </box>
        </geometry>
        <surface>
          <friction>
            <ode>
              <mu>0</mu>
              <mu2>0</mu2>
            </ode>
          </friction>
        </surface>
      </collision>
      <visual name='visual'>
        <geometry>
          <box>
            <size>0.5 0.5 0.01</size>
          </box>
        </geometry>
        <material>
          <ambient>1 0 0 1</ambient>
          <diffuse>1 0 0 1</diffuse>
          <specular>0.1 0.1 0.1 1</specular>
          <emissive>0 0 0 0</emissive>
        </material>
      </visual>
      <velocity_decay>
        <linear>0</linear>
        <angular>0</angular>
      </velocity_decay>
    </link>
    <joint name='tactile_joint_37' type='prismatic'>
      <parent>plane</parent>
      <child>tactile_37</child>
      <axis>
        <xyz>0 0 1</xyz>
        <limit>
          <lower>-1e+16</lower>
          <upper>1e+16</upper>
        </limit>
      </axis>
    </joint>
    <link name='spring_38'>
      <pose>-0.5 -1 1.3 0 -0 0</pose>
      <inertial>
        <mass>0.001</mass>
      </inertial>
      <collision name='sphere_collision'>
        <geometry>
          <sphere>
            <radius>0.25</radius>
          </sphere>
        </geometry>
        <surface>
          <friction>
            <ode>
              <mu>0</mu>
              <mu2>0</mu2>
            </ode>
          </friction>
        </surface>
      </collision>
      <visual name='visual'>
        <geometry>
          <sphere>
            <radius>0.25</radius>
          </sphere>
        </geometry>
        <material>
          <ambient>1 1 1 1</ambient>
          <diffuse>1 1 1 1</diffuse>
          <specular>0.1 0.1 0.1 1</specular>
          <emissive>0 0 0 0</emissive>
        </material>
      </visual>
      <velocity_decay>
        <linear>0</linear>
        <angular>0</angular>
      </velocity_decay>
    </link>
    <joint name='spring_joint_38' type='prismatic'>
      <parent>tactile_38</parent>
      <child>spring_38</child>
      <axis>
        <xyz>0 0 1</xyz>
        <limit>
          <lower>-1e+16</lower>
          <upper>1e+16</upper>
        </limit>
      </axis>
    </joint>
    <link name='tactile_38'>
      <pose>-0.5 -1 0.4 0 -0 0</pose>
      <inertial>
        <mass>0.001</mass>
      </inertial>
      <collision name='square_collision'>
        <geometry>
          <box>
            <size>0.5 0.5 0.01</size>
          </box>
        </geometry>
        <surface>
          <friction>
            <ode>
              <mu>0</mu>
              <mu2>0</mu2>
            </ode>
          </friction>
        </surface>
      </collision>
      <visual name='visual'>
        <geometry>
          <box>
            <size>0.5 0.5 0.01</size>
          </box>
        </geometry>
        <material>
          <ambient>1 0 0 1</ambient>
          <diffuse>1 0 0 1</diffuse>
          <specular>0.1 0.1 0.1 1</specular>
          <emissive>0 0 0 0</emissive>
        </material>
      </visual>
      <velocity_decay>
        <linear>0</linear>
        <angular>0</angular>
      </velocity_decay>
    </link>
    <joint name='tactile_joint_38' type='prismatic'>
      <parent>plane</parent>
      <child>tactile_38</child>
      <axis>
        <xyz>0 0 1</xyz>
        <limit>
          <lower>-1e+16</lower>
          <upper>1e+16</upper>
        </limit>
      </axis>
    </joint>
    <link name='spring_39'>
      <pose>0 -1 1.3 0 -0 0</pose>
      <inertial>
        <mass>0.001</mass>
      </inertial>
      <collision name='sphere_collision'>
        <geometry>
          <sphere>
            <radius>0.25</radius>
          </sphere>
        </geometry>
        <surface>
          <friction>
            <ode>
              <mu>0</mu>
              <mu2>0</mu2>
            </ode>
          </friction>
        </surface>
      </collision>
      <visual name='visual'>
        <geometry>
          <sphere>
            <radius>0.25</radius>
          </sphere>
        </geometry>
        <material>
          <ambient>1 1 1 1</ambient>
          <diffuse>1 1 1 1</diffuse>
          <specular>0.1 0.1 0.1 1</specular>
          <emissive>0 0 0 0</emissive>
        </material>
      </visual>
      <velocity_decay>
        <linear>0</linear>
        <angular>0</angular>
      </velocity_decay>
    </link>
    <joint name='spring_joint_39' type='prismatic'>
      <parent>tactile_39</parent>
      <child>spring_39</child>
      <axis>
        <xyz>0 0 1</xyz>
        <limit>
          <lower>-1e+16</lower>
          <upper>1e+16</upper>
        </limit>
      </axis>
    </joint>
    <link name='tactile_39'>
      <pose>0 -1 0.4 0 -0 0</pose>
      <inertial>
        <mass>0.001</mass>
      </inertial>
      <collision name='square_collision'>
        <geometry>
          <box>
            <size>0.5 0.5 0.01</size>
          </box>
        </geometry>
        <surface>
          <friction>
            <ode>
              <mu>0</mu>
              <mu2>0</mu2>
            </ode>
          </friction>
        </surface>
      </collision>
      <visual name='visual'>
        <geometry>
          <box>
            <size>0.5 0.5 0.01</size>
          </box>
        </geometry>
        <material>
          <ambient>1 0 0 1</ambient>
          <diffuse>1 0 0 1</diffuse>
          <specular>0.1 0.1 0.1 1</specular>
          <emissive>0 0 0 0</emissive>
        </material>
      </visual>
      <velocity_decay>
        <linear>0</linear>
        <angular>0</angular>
      </velocity_decay>
    </link>
    <joint name='tactile_joint_39' type='prismatic'>
      <parent>plane</parent>
      <child>tactile_39</child>
      <axis>
        <xyz>0 0 1</xyz>
        <limit>
          <lower>-1e+16</lower>
          <upper>1e+16</upper>
        </limit>
      </axis>
    </joint>
    <link name='spring_40'>
      <pose>0.5 -1 1.3 0 -0 0</pose>
      <inertial>
        <mass>0.001</mass>
      </inertial>
      <collision name='sphere_collision'>
        <geometry>
          <sphere>
            <radius>0.25</radius>
          </sphere>
        </geometry>
        <surface>
          <friction>
            <ode>
              <mu>0</mu>
              <mu2>0</mu2>
            </ode>
          </friction>
        </surface>
      </collision>
      <visual name='visual'>
        <geometry>
          <sphere>
            <radius>0.25</radius>
          </sphere>
        </geometry>
        <material>
          <ambient>1 1 1 1</ambient>
          <diffuse>1 1 1 1</diffuse>
          <specular>0.1 0.1 0.1 1</specular>
          <emissive>0 0 0 0</emissive>
        </material>
      </visual>
      <velocity_decay>
        <linear>0</linear>
        <angular>0</angular>
      </velocity_decay>
    </link>
    <joint name='spring_joint_40' type='prismatic'>
      <parent>tactile_40</parent>
      <child>spring_40</child>
      <axis>
        <xyz>0 0 1</xyz>
        <limit>
          <lower>-1e+16</lower>
          <upper>1e+16</upper>
        </limit>
      </axis>
    </joint>
    <link name='tactile_40'>
      <pose>0.5 -1 0.4 0 -0 0</pose>
      <inertial>
        <mass>0.001</mass>
      </inertial>
      <collision name='square_collision'>
        <geometry>
          <box>
            <size>0.5 0.5 0.01</size>
          </box>
        </geometry>
        <surface>
          <friction>
            <ode>
              <mu>0</mu>
              <mu2>0</mu2>
            </ode>
          </friction>
        </surface>
      </collision>
      <visual name='visual'>
        <geometry>
          <box>
            <size>0.5 0.5 0.01</size>
          </box>
        </geometry>
        <material>
          <ambient>1 0 0 1</ambient>
          <diffuse>1 0 0 1</diffuse>
          <specular>0.1 0.1 0.1 1</specular>
          <emissive>0 0 0 0</emissive>
        </material>
      </visual>
      <velocity_decay>
        <linear>0</linear>
        <angular>0</angular>
      </velocity_decay>
    </link>
    <joint name='tactile_joint_40' type='prismatic'>
      <parent>plane</parent>
      <child>tactile_40</child>
      <axis>
        <xyz>0 0 1</xyz>
        <limit>
          <lower>-1e+16</lower>
          <upper>1e+16</upper>
        </limit>
      </axis>
    </joint>
    <link name='spring_41'>
      <pose>1 -1 1.3 0 -0 0</pose>
      <inertial>
        <mass>0.001</mass>
      </inertial>
      <collision name='sphere_collision'>
        <geometry>
          <sphere>
            <radius>0.25</radius>
          </sphere>
        </geometry>
        <surface>
          <friction>
            <ode>
              <mu>0</mu>
              <mu2>0</mu2>
            </ode>
          </friction>
        </surface>
      </collision>
      <visual name='visual'>
        <geometry>
          <sphere>
            <radius>0.25</radius>
          </sphere>
        </geometry>
        <material>
          <ambient>1 1 1 1</ambient>
          <diffuse>1 1 1 1</diffuse>
          <specular>0.1 0.1 0.1 1</specular>
          <emissive>0 0 0 0</emissive>
        </material>
      </visual>
      <velocity_decay>
        <linear>0</linear>
        <angular>0</angular>
      </velocity_decay>
    </link>
    <joint name='spring_joint_41' type='prismatic'>
      <parent>tactile_41</parent>
      <child>spring_41</child>
      <axis>
        <xyz>0 0 1</xyz>
        <limit>
          <lower>-1e+16</lower>
          <upper>1e+16</upper>
        </limit>
      </axis>
    </joint>
    <link name='tactile_41'>
      <pose>1 -1 0.4 0 -0 0</pose>
      <inertial>
        <mass>0.001</mass>
      </inertial>
      <collision name='square_collision'>
        <geometry>
          <box>
            <size>0.5 0.5 0.01</size>
          </box>
        </geometry>
        <surface>
          <friction>
            <ode>
              <mu>0</mu>
              <mu2>0</mu2>
            </ode>
          </friction>
        </surface>
      </collision>
      <visual name='visual'>
        <geometry>
          <box>
            <size>0.5 0.5 0.01</size>
          </box>
        </geometry>
        <material>
          <ambient>1 0 0 1</ambient>
          <diffuse>1 0 0 1</diffuse>
          <specular>0.1 0.1 0.1 1</specular>
          <emissive>0 0 0 0</emissive>
        </material>
      </visual>
      <velocity_decay>
        <linear>0</linear>
        <angular>0</angular>
      </velocity_decay>
    </link>
    <joint name='tactile_joint_41' type='prismatic'>
      <parent>plane</parent>
      <child>tactile_41</child>
      <axis>
        <xyz>0 0 1</xyz>
        <limit>
          <lower>-1e+16</lower>
          <upper>1e+16</upper>
        </limit>
      </axis>
    </joint>
    <link name='spring_42'>
      <pose>1.5 -1 1.3 0 -0 0</pose>
      <inertial>
        <mass>0.001</mass>
      </inertial>
      <collision name='sphere_collision'>
        <geometry>
          <sphere>
            <radius>0.25</radius>
          </sphere>
        </geometry>
        <surface>
          <friction>
            <ode>
              <mu>0</mu>
              <mu2>0</mu2>
            </ode>
          </friction>
        </surface>
      </collision>
      <visual name='visual'>
        <geometry>
          <sphere>
            <radius>0.25</radius>
          </sphere>
        </geometry>
        <material>
          <ambient>1 1 1 1</ambient>
          <diffuse>1 1 1 1</diffuse>
          <specular>0.1 0.1 0.1 1</specular>
          <emissive>0 0 0 0</emissive>
        </material>
      </visual>
      <velocity_decay>
        <linear>0</linear>
        <angular>0</angular>
      </velocity_decay>
    </link>
    <joint name='spring_joint_42' type='prismatic'>
      <parent>tactile_42</parent>
      <child>spring_42</child>
      <axis>
        <xyz>0 0 1</xyz>
        <limit>
          <lower>-1e+16</lower>
          <upper>1e+16</upper>
        </limit>
      </axis>
    </joint>
    <link name='tactile_42'>
      <pose>1.5 -1 0.4 0 -0 0</pose>
      <inertial>
        <mass>0.001</mass>
      </inertial>
      <collision name='square_collision'>
        <geometry>
          <box>
            <size>0.5 0.5 0.01</size>
          </box>
        </geometry>
        <surface>
          <friction>
            <ode>
              <mu>0</mu>
              <mu2>0</mu2>
            </ode>
          </friction>
        </surface>
      </collision>
      <visual name='visual'>
        <geometry>
          <box>
            <size>0.5 0.5 0.01</size>
          </box>
        </geometry>
        <material>
          <ambient>1 0 0 1</ambient>
          <diffuse>1 0 0 1</diffuse>
          <specular>0.1 0.1 0.1 1</specular>
          <emissive>0 0 0 0</emissive>
        </material>
      </visual>
      <velocity_decay>
        <linear>0</linear>
        <angular>0</angular>
      </velocity_decay>
    </link>
    <joint name='tactile_joint_42' type='prismatic'>
      <parent>plane</parent>
      <child>tactile_42</child>
      <axis>
        <xyz>0 0 1</xyz>
        <limit>
          <lower>-1e+16</lower>
          <upper>1e+16</upper>
        </limit>
      </axis>
    </joint>
    <link name='spring_43'>
      <pose>-1.5 -1.5 1.3 0 -0 0</pose>
      <inertial>
        <mass>0.001</mass>
      </inertial>
      <collision name='sphere_collision'>
        <geometry>
          <sphere>
            <radius>0.25</radius>
          </sphere>
        </geometry>
        <surface>
          <friction>
            <ode>
              <mu>0</mu>
              <mu2>0</mu2>
            </ode>
          </friction>
        </surface>
      </collision>
      <visual name='visual'>
        <geometry>
          <sphere>
            <radius>0.25</radius>
          </sphere>
        </geometry>
        <material>
          <ambient>1 1 1 1</ambient>
          <diffuse>1 1 1 1</diffuse>
          <specular>0.1 0.1 0.1 1</specular>
          <emissive>0 0 0 0</emissive>
        </material>
      </visual>
      <velocity_decay>
        <linear>0</linear>
        <angular>0</angular>
      </velocity_decay>
    </link>
    <joint name='spring_joint_43' type='prismatic'>
      <parent>tactile_43</parent>
      <child>spring_43</child>
      <axis>
        <xyz>0 0 1</xyz>
        <limit>
          <lower>-1e+16</lower>
          <upper>1e+16</upper>
        </limit>
      </axis>
    </joint>
    <link name='tactile_43'>
      <pose>-1.5 -1.5 0.4 0 -0 0</pose>
      <inertial>
        <mass>0.001</mass>
      </inertial>
      <collision name='square_collision'>
        <geometry>
          <box>
            <size>0.5 0.5 0.01</size>
          </box>
        </geometry>
        <surface>
          <friction>
            <ode>
              <mu>0</mu>
              <mu2>0</mu2>
            </ode>
          </friction>
        </surface>
      </collision>
      <visual name='visual'>
        <geometry>
          <box>
            <size>0.5 0.5 0.01</size>
          </box>
        </geometry>
        <material>
          <ambient>1 0 0 1</ambient>
          <diffuse>1 0 0 1</diffuse>
          <specular>0.1 0.1 0.1 1</specular>
          <emissive>0 0 0 0</emissive>
        </material>
      </visual>
      <velocity_decay>
        <linear>0</linear>
        <angular>0</angular>
      </velocity_decay>
    </link>
    <joint name='tactile_joint_43' type='prismatic'>
      <parent>plane</parent>
      <child>tactile_43</child>
      <axis>
        <xyz>0 0 1</xyz>
        <limit>
          <lower>-1e+16</lower>
          <upper>1e+16</upper>
        </limit>
      </axis>
    </joint>
    <link name='spring_44'>
      <pose>-1 -1.5 1.3 0 -0 0</pose>
      <inertial>
        <mass>0.001</mass>
      </inertial>
      <collision name='sphere_collision'>
        <geometry>
          <sphere>
            <radius>0.25</radius>
          </sphere>
        </geometry>
        <surface>
          <friction>
            <ode>
              <mu>0</mu>
              <mu2>0</mu2>
            </ode>
          </friction>
        </surface>
      </collision>
      <visual name='visual'>
        <geometry>
          <sphere>
            <radius>0.25</radius>
          </sphere>
        </geometry>
        <material>
          <ambient>1 1 1 1</ambient>
          <diffuse>1 1 1 1</diffuse>
          <specular>0.1 0.1 0.1 1</specular>
          <emissive>0 0 0 0</emissive>
        </material>
      </visual>
      <velocity_decay>
        <linear>0</linear>
        <angular>0</angular>
      </velocity_decay>
    </link>
    <joint name='spring_joint_44' type='prismatic'>
      <parent>tactile_44</parent>
      <child>spring_44</child>
      <axis>
        <xyz>0 0 1</xyz>
        <limit>
          <lower>-1e+16</lower>
          <upper>1e+16</upper>
        </limit>
      </axis>
    </joint>
    <link name='tactile_44'>
      <pose>-1 -1.5 0.4 0 -0 0</pose>
      <inertial>
        <mass>0.001</mass>
      </inertial>
      <collision name='square_collision'>
        <geometry>
          <box>
            <size>0.5 0.5 0.01</size>
          </box>
        </geometry>
        <surface>
          <friction>
            <ode>
              <mu>0</mu>
              <mu2>0</mu2>
            </ode>
          </friction>
        </surface>
      </collision>
      <visual name='visual'>
        <geometry>
          <box>
            <size>0.5 0.5 0.01</size>
          </box>
        </geometry>
        <material>
          <ambient>1 0 0 1</ambient>
          <diffuse>1 0 0 1</diffuse>
          <specular>0.1 0.1 0.1 1</specular>
          <emissive>0 0 0 0</emissive>
        </material>
      </visual>
      <velocity_decay>
        <linear>0</linear>
        <angular>0</angular>
      </velocity_decay>
    </link>
    <joint name='tactile_joint_44' type='prismatic'>
      <parent>plane</parent>
      <child>tactile_44</child>
      <axis>
        <xyz>0 0 1</xyz>
        <limit>
          <lower>-1e+16</lower>
          <upper>1e+16</upper>
        </limit>
      </axis>
    </joint>
    <link name='spring_45'>
      <pose>-0.5 -1.5 1.3 0 -0 0</pose>
      <inertial>
        <mass>0.001</mass>
      </inertial>
      <collision name='sphere_collision'>
        <geometry>
          <sphere>
            <radius>0.25</radius>
          </sphere>
        </geometry>
        <surface>
          <friction>
            <ode>
              <mu>0</mu>
              <mu2>0</mu2>
            </ode>
          </friction>
        </surface>
      </collision>
      <visual name='visual'>
        <geometry>
          <sphere>
            <radius>0.25</radius>
          </sphere>
        </geometry>
        <material>
          <ambient>1 1 1 1</ambient>
          <diffuse>1 1 1 1</diffuse>
          <specular>0.1 0.1 0.1 1</specular>
          <emissive>0 0 0 0</emissive>
        </material>
      </visual>
      <velocity_decay>
        <linear>0</linear>
        <angular>0</angular>
      </velocity_decay>
    </link>
    <joint name='spring_joint_45' type='prismatic'>
      <parent>tactile_45</parent>
      <child>spring_45</child>
      <axis>
        <xyz>0 0 1</xyz>
        <limit>
          <lower>-1e+16</lower>
          <upper>1e+16</upper>
        </limit>
      </axis>
    </joint>
    <link name='tactile_45'>
      <pose>-0.5 -1.5 0.4 0 -0 0</pose>
      <inertial>
        <mass>0.001</mass>
      </inertial>
      <collision name='square_collision'>
        <geometry>
          <box>
            <size>0.5 0.5 0.01</size>
          </box>
        </geometry>
        <surface>
          <friction>
            <ode>
              <mu>0</mu>
              <mu2>0</mu2>
            </ode>
          </friction>
        </surface>
      </collision>
      <visual name='visual'>
        <geometry>
          <box>
            <size>0.5 0.5 0.01</size>
          </box>
        </geometry>
        <material>
          <ambient>1 0 0 1</ambient>
          <diffuse>1 0 0 1</diffuse>
          <specular>0.1 0.1 0.1 1</specular>
          <emissive>0 0 0 0</emissive>
        </material>
      </visual>
      <velocity_decay>
        <linear>0</linear>
        <angular>0</angular>
      </velocity_decay>
    </link>
    <joint name='tactile_joint_45' type='prismatic'>
      <parent>plane</parent>
      <child>tactile_45</child>
      <axis>
        <xyz>0 0 1</xyz>
        <limit>
          <lower>-1e+16</lower>
          <upper>1e+16</upper>
        </limit>
      </axis>
    </joint>
    <link name='spring_46'>
      <pose>0 -1.5 1.3 0 -0 0</pose>
      <inertial>
        <mass>0.001</mass>
      </inertial>
      <collision name='sphere_collision'>
        <geometry>
          <sphere>
            <radius>0.25</radius>
          </sphere>
        </geometry>
        <surface>
          <friction>
            <ode>
              <mu>0</mu>
              <mu2>0</mu2>
            </ode>
          </friction>
        </surface>
      </collision>
      <visual name='visual'>
        <geometry>
          <sphere>
            <radius>0.25</radius>
          </sphere>
        </geometry>
        <material>
          <ambient>1 1 1 1</ambient>
          <diffuse>1 1 1 1</diffuse>
          <specular>0.1 0.1 0.1 1</specular>
          <emissive>0 0 0 0</emissive>
        </material>
      </visual>
      <velocity_decay>
        <linear>0</linear>
        <angular>0</angular>
      </velocity_decay>
    </link>
    <joint name='spring_joint_46' type='prismatic'>
      <parent>tactile_46</parent>
      <child>spring_46</child>
      <axis>
        <xyz>0 0 1</xyz>
        <limit>
          <lower>-1e+16</lower>
          <upper>1e+16</upper>
        </limit>
      </axis>
    </joint>
    <link name='tactile_46'>
      <pose>0 -1.5 0.4 0 -0 0</pose>
      <inertial>
        <mass>0.001</mass>
      </inertial>
      <collision name='square_collision'>
        <geometry>
          <box>
            <size>0.5 0.5 0.01</size>
          </box>
        </geometry>
        <surface>
          <friction>
            <ode>
              <mu>0</mu>
              <mu2>0</mu2>
            </ode>
          </friction>
        </surface>
      </collision>
      <visual name='visual'>
        <geometry>
          <box>
            <size>0.5 0.5 0.01</size>
          </box>
        </geometry>
        <material>
          <ambient>1 0 0 1</ambient>
          <diffuse>1 0 0 1</diffuse>
          <specular>0.1 0.1 0.1 1</specular>
          <emissive>0 0 0 0</emissive>
        </material>
      </visual>
      <velocity_decay>
        <linear>0</linear>
        <angular>0</angular>
      </velocity_decay>
    </link>
    <joint name='tactile_joint_46' type='prismatic'>
      <parent>plane</parent>
      <child>tactile_46</child>
      <axis>
        <xyz>0 0 1</xyz>
        <limit>
          <lower>-1e+16</lower>
          <upper>1e+16</upper>
        </limit>
      </axis>
    </joint>
    <link name='spring_47'>
      <pose>0.5 -1.5 1.3 0 -0 0</pose>
      <inertial>
        <mass>0.001</mass>
      </inertial>
      <collision name='sphere_collision'>
        <geometry>
          <sphere>
            <radius>0.25</radius>
          </sphere>
        </geometry>
        <surface>
          <friction>
            <ode>
              <mu>0</mu>
              <mu2>0</mu2>
            </ode>
          </friction>
        </surface>
      </collision>
      <visual name='visual'>
        <geometry>
          <sphere>
            <radius>0.25</radius>
          </sphere>
        </geometry>
        <material>
          <ambient>1 1 1 1</ambient>
          <diffuse>1 1 1 1</diffuse>
          <specular>0.1 0.1 0.1 1</specular>
          <emissive>0 0 0 0</emissive>
        </material>
      </visual>
      <velocity_decay>
        <linear>0</linear>
        <angular>0</angular>
      </velocity_decay>
    </link>
    <joint name='spring_joint_47' type='prismatic'>
      <parent>tactile_47</parent>
      <child>spring_47</child>
      <axis>
        <xyz>0 0 1</xyz>
        <limit>
          <lower>-1e+16</lower>
          <upper>1e+16</upper>
        </limit>
      </axis>
    </joint>
    <link name='tactile_47'>
      <pose>0.5 -1.5 0.4 0 -0 0</pose>
      <inertial>
        <mass>0.001</mass>
      </inertial>
      <collision name='square_collision'>
        <geometry>
          <box>
            <size>0.5 0.5 0.01</size>
          </box>
        </geometry>
        <surface>
          <friction>
            <ode>
              <mu>0</mu>
              <mu2>0</mu2>
            </ode>
          </friction>
        </surface>
      </collision>
      <visual name='visual'>
        <geometry>
          <box>
            <size>0.5 0.5 0.01</size>
          </box>
        </geometry>
        <material>
          <ambient>1 0 0 1</ambient>
          <diffuse>1 0 0 1</diffuse>
          <specular>0.1 0.1 0.1 1</specular>
          <emissive>0 0 0 0</emissive>
        </material>
      </visual>
      <velocity_decay>
        <linear>0</linear>
        <angular>0</angular>
      </velocity_decay>
    </link>
    <joint name='tactile_joint_47' type='prismatic'>
      <parent>plane</parent>
      <child>tactile_47</child>
      <axis>
        <xyz>0 0 1</xyz>
        <limit>
          <lower>-1e+16</lower>
          <upper>1e+16</upper>
        </limit>
      </axis>
    </joint>
    <link name='spring_48'>
      <pose>1 -1.5 1.3 0 -0 0</pose>
      <inertial>
        <mass>0.001</mass>
      </inertial>
      <collision name='sphere_collision'>
        <geometry>
          <sphere>
            <radius>0.25</radius>
          </sphere>
        </geometry>
        <surface>
          <friction>
            <ode>
              <mu>0</mu>
              <mu2>0</mu2>
            </ode>
          </friction>
        </surface>
      </collision>
      <visual name='visual'>
        <geometry>
          <sphere>
            <radius>0.25</radius>
          </sphere>
        </geometry>
        <material>
          <ambient>1 1 1 1</ambient>
          <diffuse>1 1 1 1</diffuse>
          <specular>0.1 0.1 0.1 1</specular>
          <emissive>0 0 0 0</emissive>
        </material>
      </visual>
      <velocity_decay>
        <linear>0</linear>
        <angular>0</angular>
      </velocity_decay>
    </link>
    <joint name='spring_joint_48' type='prismatic'>
      <parent>tactile_48</parent>
      <child>spring_48</child>
      <axis>
        <xyz>0 0 1</xyz>
        <limit>
          <lower>-1e+16</lower>
          <upper>1e+16</upper>
        </limit>
      </axis>
    </joint>
    <link name='tactile_48'>
      <pose>1 -1.5 0.4 0 -0 0</pose>
      <inertial>
        <mass>0.001</mass>
      </inertial>
      <collision name='square_collision'>
        <geometry>
          <box>
            <size>0.5 0.5 0.01</size>
          </box>
        </geometry>
        <surface>
          <friction>
            <ode>
              <mu>0</mu>
              <mu2>0</mu2>
            </ode>
          </friction>
        </surface>
      </collision>
      <visual name='visual'>
        <geometry>
          <box>
            <size>0.5 0.5 0.01</size>
          </box>
        </geometry>
        <material>
          <ambient>1 0 0 1</ambient>
          <diffuse>1 0 0 1</diffuse>
          <specular>0.1 0.1 0.1 1</specular>
          <emissive>0 0 0 0</emissive>
        </material>
      </visual>
      <velocity_decay>
        <linear>0</linear>
        <angular>0</angular>
      </velocity_decay>
    </link>
    <joint name='tactile_joint_48' type='prismatic'>
      <parent>plane</parent>
      <child>tactile_48</child>
      <axis>
        <xyz>0 0 1</xyz>
        <limit>
          <lower>-1e+16</lower>
          <upper>1e+16</upper>
        </limit>
      </axis>
    </joint>
    <link name='spring_49'>
      <pose>1.5 -1.5 1.3 0 -0 0</pose>
      <inertial>
        <mass>0.001</mass>
      </inertial>
      <collision name='sphere_collision'>
        <geometry>
          <sphere>
            <radius>0.25</radius>
          </sphere>
        </geometry>
        <surface>
          <friction>
            <ode>
              <mu>0</mu>
              <mu2>0</mu2>
            </ode>
          </friction>
        </surface>
      </collision>
      <visual name='visual'>
        <geometry>
          <sphere>
            <radius>0.25</radius>
          </sphere>
        </geometry>
        <material>
          <ambient>1 1 1 1</ambient>
          <diffuse>1 1 1 1</diffuse>
          <specular>0.1 0.1 0.1 1</specular>
          <emissive>0 0 0 0</emissive>
        </material>
      </visual>
      <velocity_decay>
        <linear>0</linear>
        <angular>0</angular>
      </velocity_decay>
    </link>
    <joint name='spring_joint_49' type='prismatic'>
      <parent>tactile_49</parent>
      <child>spring_49</child>
      <axis>
        <xyz>0 0 1</xyz>
        <limit>
          <lower>-1e+16</lower>
          <upper>1e+16</upper>
        </limit>
      </axis>
    </joint>
    <link name='tactile_49'>
      <pose>1.5 -1.5 0.4 0 -0 0</pose>
      <inertial>
        <mass>0.001</mass>
      </inertial>
      <collision name='square_collision'>
        <geometry>
          <box>
            <size>0.5 0.5 0.01</size>
          </box>
        </geometry>
        <surface>
          <friction>
            <ode>
              <mu>0</mu>
              <mu2>0</mu2>
            </ode>
          </friction>
        </surface>
      </collision>
      <visual name='visual'>
        <geometry>
          <box>
            <size>0.5 0.5 0.01</size>
          </box>
        </geometry>
        <material>
          <ambient>1 0 0 1</ambient>
          <diffuse>1 0 0 1</diffuse>
          <specular>0.1 0.1 0.1 1</specular>
          <emissive>0 0 0 0</emissive>
        </material>
      </visual>
      <velocity_decay>
        <linear>0</linear>
        <angular>0</angular>
      </velocity_decay>
    </link>
    <joint name='tactile_joint_49' type='prismatic'>
      <parent>plane</parent>
      <child>tactile_49</child>
      <axis>
        <xyz>0 0 1</xyz>
        <limit>
          <lower>-1e+16</lower>
          <upper>1e+16</upper>
        </limit>
      </axis>
    </joint>
    <plugin name='spring_joint' filename='libspring_joint.so'/>
    <plugin name='tactile_joint' filename='libtactile_joint.so'/>
    <plugin name='plane_joint' filename='libplane_joint.so'/>
  </model>
</sdf>
