<?xml version="1.0" ?>
<sdf version="1.4">
   
    <model name="spring_board">
      <pose>0 0 0 0 0 0</pose>
      <link name="plane">
        <pose>0 0 0.1 0 0 0</pose>
        <collision name="collision">
          <geometry>
            <box>
              <size>4 4 0.2</size>
            </box>
          </geometry>
        </collision>
        <visual name="visual">
          <geometry>
            <box>
              <size>4 4 0.2</size>
            </box>
          </geometry>
        </visual>
       </link>

      <link name="spring_1">
        <pose>-1.5 1.5 1.3 0 0 0</pose>
        <inertial>
          <mass>0.001</mass>
        </inertial>
        <collision name="sphere_collision">
          <geometry>
            <sphere>
              <radius>0.25</radius>
            </sphere>
          </geometry>
            <surface>
              <friction>
                <ode>
                  <mu>0.0</mu>
                  <mu2>0.0</mu2>
                </ode>
              </friction>
            </surface>
        </collision>
        <visual name="visual">
          <geometry>
            <sphere>
              <radius>0.25</radius>
            </sphere>
          </geometry>
        </visual>
       </link>

      <link name="spring_2">
        <pose>-1.0 1.5 1.3 0 0 0</pose>
        <inertial>
          <mass>0.001</mass>
        </inertial>
        <collision name="sphere_collision">
          <geometry>
            <sphere>
              <radius>0.25</radius>
            </sphere>
          </geometry>
            <surface>
              <friction>
                <ode>
                  <mu>0.0</mu>
                  <mu2>0.0</mu2>
                </ode>
              </friction>
            </surface>
        </collision>
        <visual name="visual">
          <geometry>
            <sphere>
              <radius>0.25</radius>
            </sphere>
          </geometry>
        </visual>
       </link>

      <link name="spring_3">
        <pose>-0.5 1.5 1.3 0 0 0</pose>
        <inertial>
          <mass>0.001</mass>
        </inertial>
        <collision name="sphere_collision">
          <geometry>
            <sphere>
              <radius>0.25</radius>
            </sphere>
          </geometry>
            <surface>
              <friction>
                <ode>
                  <mu>0.0</mu>
                  <mu2>0.0</mu2>
                </ode>
              </friction>
            </surface>
        </collision>
        <visual name="visual">
          <geometry>
            <sphere>
              <radius>0.25</radius>
            </sphere>
          </geometry>
        </visual>
       </link>

      <link name="spring_4">
        <pose>0 1.5 1.3 0 0 0</pose>
        <inertial>
          <mass>0.001</mass>
        </inertial>
        <collision name="sphere_collision">
          <geometry>
            <sphere>
              <radius>0.25</radius>
            </sphere>
          </geometry>
            <surface>
              <friction>
                <ode>
                  <mu>0.0</mu>
                  <mu2>0.0</mu2>
                </ode>
              </friction>
            </surface>
        </collision>
        <visual name="visual">
          <geometry>
            <sphere>
              <radius>0.25</radius>
            </sphere>
          </geometry>
        </visual>
       </link>

      <link name="spring_5">
        <pose>0.5 1.5 1.3 0 0 0</pose>
        <inertial>
          <mass>0.001</mass>
        </inertial>
        <collision name="sphere_collision">
          <geometry>
            <sphere>
              <radius>0.25</radius>
            </sphere>
          </geometry>
            <surface>
              <friction>
                <ode>
                  <mu>0.0</mu>
                  <mu2>0.0</mu2>
                </ode>
              </friction>
            </surface>
        </collision>
        <visual name="visual">
          <geometry>
            <sphere>
              <radius>0.25</radius>
            </sphere>
          </geometry>
        </visual>
       </link>

      <link name="spring_6">
        <pose>1.0 1.5 1.3 0 0 0</pose>
        <inertial>
          <mass>0.001</mass>
        </inertial>
        <collision name="sphere_collision">
          <geometry>
            <sphere>
              <radius>0.25</radius>
            </sphere>
          </geometry>
            <surface>
              <friction>
                <ode>
                  <mu>0.0</mu>
                  <mu2>0.0</mu2>
                </ode>
              </friction>
            </surface>
        </collision>
        <visual name="visual">
          <geometry>
            <sphere>
              <radius>0.25</radius>
            </sphere>
          </geometry>
        </visual>
       </link>

      <link name="spring_7">
        <pose>1.5 1.5 1.3 0 0 0</pose>
        <inertial>
          <mass>0.001</mass>
        </inertial>
        <collision name="sphere_collision">
          <geometry>
            <sphere>
              <radius>0.25</radius>
            </sphere>
          </geometry>
            <surface>
              <friction>
                <ode>
                  <mu>0.0</mu>
                  <mu2>0.0</mu2>
                </ode>
              </friction>
            </surface>
        </collision>
        <visual name="visual">
          <geometry>
            <sphere>
              <radius>0.25</radius>
            </sphere>
          </geometry>
        </visual>
       </link>

      <link name="spring_8">
        <pose>-1.5 1 1.3 0 0 0</pose>
        <inertial>
          <mass>0.001</mass>
        </inertial>
        <collision name="sphere_collision">
          <geometry>
            <sphere>
              <radius>0.25</radius>
            </sphere>
          </geometry>
            <surface>
              <friction>
                <ode>
                  <mu>0.0</mu>
                  <mu2>0.0</mu2>
                </ode>
              </friction>
            </surface>
        </collision>
        <visual name="visual">
          <geometry>
            <sphere>
              <radius>0.25</radius>
            </sphere>
          </geometry>
        </visual>
       </link>

      <link name="spring_9">
        <pose>-1.0 1 1.3 0 0 0</pose>
        <inertial>
          <mass>0.001</mass>
        </inertial>
        <collision name="sphere_collision">
          <geometry>
            <sphere>
              <radius>0.25</radius>
            </sphere>
          </geometry>
            <surface>
              <friction>
                <ode>
                  <mu>0.0</mu>
                  <mu2>0.0</mu2>
                </ode>
              </friction>
            </surface>
        </collision>
        <visual name="visual">
          <geometry>
            <sphere>
              <radius>0.25</radius>
            </sphere>
          </geometry>
        </visual>
       </link>

      <link name="spring_10">
        <pose>-0.5 1 1.3 0 0 0</pose>
        <inertial>
          <mass>0.001</mass>
        </inertial>
        <collision name="sphere_collision">
          <geometry>
            <sphere>
              <radius>0.25</radius>
            </sphere>
          </geometry>
            <surface>
              <friction>
                <ode>
                  <mu>0.0</mu>
                  <mu2>0.0</mu2>
                </ode>
              </friction>
            </surface>
        </collision>
        <visual name="visual">
          <geometry>
            <sphere>
              <radius>0.25</radius>
            </sphere>
          </geometry>
        </visual>
       </link>

      <link name="spring_11">
        <pose>0 1 1.3 0 0 0</pose>
        <inertial>
          <mass>0.001</mass>
        </inertial>
        <collision name="sphere_collision">
          <geometry>
            <sphere>
              <radius>0.25</radius>
            </sphere>
          </geometry>
            <surface>
              <friction>
                <ode>
                  <mu>0.0</mu>
                  <mu2>0.0</mu2>
                </ode>
              </friction>
            </surface>
        </collision>
        <visual name="visual">
          <geometry>
            <sphere>
              <radius>0.25</radius>
            </sphere>
          </geometry>
        </visual>
       </link>

      <link name="spring_12">
        <pose>0.5 1 1.3 0 0 0</pose>
        <inertial>
          <mass>0.001</mass>
        </inertial>
        <collision name="sphere_collision">
          <geometry>
            <sphere>
              <radius>0.25</radius>
            </sphere>
          </geometry>
            <surface>
              <friction>
                <ode>
                  <mu>0.0</mu>
                  <mu2>0.0</mu2>
                </ode>
              </friction>
            </surface>
        </collision>
        <visual name="visual">
          <geometry>
            <sphere>
              <radius>0.25</radius>
            </sphere>
          </geometry>
        </visual>
       </link>

      <link name="spring_13">
        <pose>1 1 1.3 0 0 0</pose>
        <inertial>
          <mass>0.001</mass>
        </inertial>
        <collision name="sphere_collision">
          <geometry>
            <sphere>
              <radius>0.25</radius>
            </sphere>
          </geometry>
            <surface>
              <friction>
                <ode>
                  <mu>0.0</mu>
                  <mu2>0.0</mu2>
                </ode>
              </friction>
            </surface>
        </collision>
        <visual name="visual">
          <geometry>
            <sphere>
              <radius>0.25</radius>
            </sphere>
          </geometry>
        </visual>
       </link>

      <link name="spring_14">
        <pose>1.5 1 1.3 0 0 0</pose>
        <inertial>
          <mass>0.001</mass>
        </inertial>
        <collision name="sphere_collision">
          <geometry>
            <sphere>
              <radius>0.25</radius>
            </sphere>
          </geometry>
            <surface>
              <friction>
                <ode>
                  <mu>0.0</mu>
                  <mu2>0.0</mu2>
                </ode>
              </friction>
            </surface>
        </collision>
        <visual name="visual">
          <geometry>
            <sphere>
              <radius>0.25</radius>
            </sphere>
          </geometry>
        </visual>
       </link>

      <link name="spring_15">
        <pose>-1.5 0.5 1.3 0 0 0</pose>
        <inertial>
          <mass>0.001</mass>
        </inertial>
        <collision name="sphere_collision">
          <geometry>
            <sphere>
              <radius>0.25</radius>
            </sphere>
          </geometry>
            <surface>
              <friction>
                <ode>
                  <mu>0.0</mu>
                  <mu2>0.0</mu2>
                </ode>
              </friction>
            </surface>
        </collision>
        <visual name="visual">
          <geometry>
            <sphere>
              <radius>0.25</radius>
            </sphere>
          </geometry>
        </visual>
       </link>

      <link name="spring_16">
        <pose>-1 0.5 1.3 0 0 0</pose>
        <inertial>
          <mass>0.001</mass>
        </inertial>
        <collision name="sphere_collision">
          <geometry>
            <sphere>
              <radius>0.25</radius>
            </sphere>
          </geometry>
            <surface>
              <friction>
                <ode>
                  <mu>0.0</mu>
                  <mu2>0.0</mu2>
                </ode>
              </friction>
            </surface>
        </collision>
        <visual name="visual">
          <geometry>
            <sphere>
              <radius>0.25</radius>
            </sphere>
          </geometry>
        </visual>
       </link>

      <link name="spring_17">
        <pose>-0.5 0.5 1.3 0 0 0</pose>
        <inertial>
          <mass>0.001</mass>
        </inertial>
        <collision name="sphere_collision">
          <geometry>
            <sphere>
              <radius>0.25</radius>
            </sphere>
          </geometry>
            <surface>
              <friction>
                <ode>
                  <mu>0.0</mu>
                  <mu2>0.0</mu2>
                </ode>
              </friction>
            </surface>
        </collision>
        <visual name="visual">
          <geometry>
            <sphere>
              <radius>0.25</radius>
            </sphere>
          </geometry>
        </visual>
       </link>

      <link name="spring_18">
        <pose>0 0.5 1.3 0 0 0</pose>
        <inertial>
          <mass>0.001</mass>
        </inertial>
        <collision name="sphere_collision">
          <geometry>
            <sphere>
              <radius>0.25</radius>
            </sphere>
          </geometry>
            <surface>
              <friction>
                <ode>
                  <mu>0.0</mu>
                  <mu2>0.0</mu2>
                </ode>
              </friction>
            </surface>
        </collision>
        <visual name="visual">
          <geometry>
            <sphere>
              <radius>0.25</radius>
            </sphere>
          </geometry>
        </visual>
       </link>

      <link name="spring_19">
        <pose>0.5 0.5 1.3 0 0 0</pose>
        <inertial>
          <mass>0.001</mass>
        </inertial>
        <collision name="sphere_collision">
          <geometry>
            <sphere>
              <radius>0.25</radius>
            </sphere>
          </geometry>
            <surface>
              <friction>
                <ode>
                  <mu>0.0</mu>
                  <mu2>0.0</mu2>
                </ode>
              </friction>
            </surface>
        </collision>
        <visual name="visual">
          <geometry>
            <sphere>
              <radius>0.25</radius>
            </sphere>
          </geometry>
        </visual>
       </link>

      <link name="spring_20">
        <pose>1 0.5 1.3 0 0 0</pose>
        <inertial>
          <mass>0.001</mass>
        </inertial>
        <collision name="sphere_collision">
          <geometry>
            <sphere>
              <radius>0.25</radius>
            </sphere>
          </geometry>
            <surface>
              <friction>
                <ode>
                  <mu>0.0</mu>
                  <mu2>0.0</mu2>
                </ode>
              </friction>
            </surface>
        </collision>
        <visual name="visual">
          <geometry>
            <sphere>
              <radius>0.25</radius>
            </sphere>
          </geometry>
        </visual>
       </link>

      <link name="spring_21">
        <pose>1.5 0.5 1.3 0 0 0</pose>
        <inertial>
          <mass>0.001</mass>
        </inertial>
        <collision name="sphere_collision">
          <geometry>
            <sphere>
              <radius>0.25</radius>
            </sphere>
          </geometry>
            <surface>
              <friction>
                <ode>
                  <mu>0.0</mu>
                  <mu2>0.0</mu2>
                </ode>
              </friction>
            </surface>
        </collision>
        <visual name="visual">
          <geometry>
            <sphere>
              <radius>0.25</radius>
            </sphere>
          </geometry>
        </visual>
       </link>

      <link name="spring_22">
        <pose>-1.5 0 1.3 0 0 0</pose>
        <inertial>
          <mass>0.001</mass>
        </inertial>
        <collision name="sphere_collision">
          <geometry>
            <sphere>
              <radius>0.25</radius>
            </sphere>
          </geometry>
            <surface>
              <friction>
                <ode>
                  <mu>0.0</mu>
                  <mu2>0.0</mu2>
                </ode>
              </friction>
            </surface>
        </collision>
        <visual name="visual">
          <geometry>
            <sphere>
              <radius>0.25</radius>
            </sphere>
          </geometry>
        </visual>
       </link>

      <link name="spring_23">
        <pose>-1 0 1.3 0 0 0</pose>
        <inertial>
          <mass>0.001</mass>
        </inertial>
        <collision name="sphere_collision">
          <geometry>
            <sphere>
              <radius>0.25</radius>
            </sphere>
          </geometry>
            <surface>
              <friction>
                <ode>
                  <mu>0.0</mu>
                  <mu2>0.0</mu2>
                </ode>
              </friction>
            </surface>
        </collision>
        <visual name="visual">
          <geometry>
            <sphere>
              <radius>0.25</radius>
            </sphere>
          </geometry>
        </visual>
       </link>

      <link name="spring_24">
        <pose>-0.5 0 1.3 0 0 0</pose>
        <inertial>
          <mass>0.001</mass>
        </inertial>
        <collision name="sphere_collision">
          <geometry>
            <sphere>
              <radius>0.25</radius>
            </sphere>
          </geometry>
            <surface>
              <friction>
                <ode>
                  <mu>0.0</mu>
                  <mu2>0.0</mu2>
                </ode>
              </friction>
            </surface>
        </collision>
        <visual name="visual">
          <geometry>
            <sphere>
              <radius>0.25</radius>
            </sphere>
          </geometry>
        </visual>
       </link>

      <link name="spring_25">
        <pose>0 0 1.3 0 0 0</pose>
        <inertial>
          <mass>0.001</mass>
        </inertial>
        <collision name="sphere_collision">
          <geometry>
            <sphere>
              <radius>0.25</radius>
            </sphere>
          </geometry>
            <surface>
              <friction>
                <ode>
                  <mu>0.0</mu>
                  <mu2>0.0</mu2>
                </ode>
              </friction>
            </surface>
        </collision>
        <visual name="visual">
          <geometry>
            <sphere>
              <radius>0.25</radius>
            </sphere>
          </geometry>
        </visual>
       </link>

       <link name="spring_26">
        <pose>0.5 0 1.3 0 0 0</pose>
        <inertial>
          <mass>0.001</mass>
        </inertial>
        <collision name="sphere_collision">
          <geometry>
            <sphere>
              <radius>0.25</radius>
            </sphere>
          </geometry>
            <surface>
              <friction>
                <ode>
                  <mu>0.0</mu>
                  <mu2>0.0</mu2>
                </ode>
              </friction>
            </surface>
        </collision>
        <visual name="visual">
          <geometry>
            <sphere>
              <radius>0.25</radius>
            </sphere>
          </geometry>
        </visual>
       </link>

      <link name="spring_27">
        <pose>1 0 1.3 0 0 0</pose>
        <inertial>
          <mass>0.001</mass>
        </inertial>
        <collision name="sphere_collision">
          <geometry>
            <sphere>
              <radius>0.25</radius>
            </sphere>
          </geometry>
            <surface>
              <friction>
                <ode>
                  <mu>0.0</mu>
                  <mu2>0.0</mu2>
                </ode>
              </friction>
            </surface>
        </collision>
        <visual name="visual">
          <geometry>
            <sphere>
              <radius>0.25</radius>
            </sphere>
          </geometry>
        </visual>
       </link>

      <link name="spring_28">
        <pose>1.5 0 1.3 0 0 0</pose>
        <inertial>
          <mass>0.001</mass>
        </inertial>
        <collision name="sphere_collision">
          <geometry>
            <sphere>
              <radius>0.25</radius>
            </sphere>
          </geometry>
            <surface>
              <friction>
                <ode>
                  <mu>0.0</mu>
                  <mu2>0.0</mu2>
                </ode>
              </friction>
            </surface>
        </collision>
        <visual name="visual">
          <geometry>
            <sphere>
              <radius>0.25</radius>
            </sphere>
          </geometry>
        </visual>
       </link>

      <link name="spring_29">
        <pose>-1.5 -0.5 1.3 0 0 0</pose>
        <inertial>
          <mass>0.001</mass>
        </inertial>
        <collision name="sphere_collision">
          <geometry>
            <sphere>
              <radius>0.25</radius>
            </sphere>
          </geometry>
            <surface>
              <friction>
                <ode>
                  <mu>0.0</mu>
                  <mu2>0.0</mu2>
                </ode>
              </friction>
            </surface>
        </collision>
        <visual name="visual">
          <geometry>
            <sphere>
              <radius>0.25</radius>
            </sphere>
          </geometry>
        </visual>
       </link>

      <link name="spring_30">
        <pose>-1 -0.5 1.3 0 0 0</pose>
        <inertial>
          <mass>0.001</mass>
        </inertial>
        <collision name="sphere_collision">
          <geometry>
            <sphere>
              <radius>0.25</radius>
            </sphere>
          </geometry>
            <surface>
              <friction>
                <ode>
                  <mu>0.0</mu>
                  <mu2>0.0</mu2>
                </ode>
              </friction>
            </surface>
        </collision>
        <visual name="visual">
          <geometry>
            <sphere>
              <radius>0.25</radius>
            </sphere>
          </geometry>
        </visual>
       </link>

      <link name="spring_31">
        <pose>-0.5 -0.5 1.3 0 0 0</pose>
        <inertial>
          <mass>0.001</mass>
        </inertial>
        <collision name="sphere_collision">
          <geometry>
            <sphere>
              <radius>0.25</radius>
            </sphere>
          </geometry>
            <surface>
              <friction>
                <ode>
                  <mu>0.0</mu>
                  <mu2>0.0</mu2>
                </ode>
              </friction>
            </surface>
        </collision>
        <visual name="visual">
          <geometry>
            <sphere>
              <radius>0.25</radius>
            </sphere>
          </geometry>
        </visual>
       </link>

      <link name="spring_32">
        <pose>0 -0.5 1.3 0 0 0</pose>
        <inertial>
          <mass>0.001</mass>
        </inertial>
        <collision name="sphere_collision">
          <geometry>
            <sphere>
              <radius>0.25</radius>
            </sphere>
          </geometry>
            <surface>
              <friction>
                <ode>
                  <mu>0.0</mu>
                  <mu2>0.0</mu2>
                </ode>
              </friction>
            </surface>
        </collision>
        <visual name="visual">
          <geometry>
            <sphere>
              <radius>0.25</radius>
            </sphere>
          </geometry>
        </visual>
       </link>

      <link name="spring_33">
        <pose>0.5 -0.5 1.3 0 0 0</pose>
        <inertial>
          <mass>0.001</mass>
        </inertial>
        <collision name="sphere_collision">
          <geometry>
            <sphere>
              <radius>0.25</radius>
            </sphere>
          </geometry>
            <surface>
              <friction>
                <ode>
                  <mu>0.0</mu>
                  <mu2>0.0</mu2>
                </ode>
              </friction>
            </surface>
        </collision>
        <visual name="visual">
          <geometry>
            <sphere>
              <radius>0.25</radius>
            </sphere>
          </geometry>
        </visual>
       </link>

      <link name="spring_34">
        <pose>1 -0.5 1.3 0 0 0</pose>
        <inertial>
          <mass>0.001</mass>
        </inertial>
        <collision name="sphere_collision">
          <geometry>
            <sphere>
              <radius>0.25</radius>
            </sphere>
          </geometry>
            <surface>
              <friction>
                <ode>
                  <mu>0.0</mu>
                  <mu2>0.0</mu2>
                </ode>
              </friction>
            </surface>
        </collision>
        <visual name="visual">
          <geometry>
            <sphere>
              <radius>0.25</radius>
            </sphere>
          </geometry>
        </visual>
       </link>

      <link name="spring_35">
        <pose>1.5 -0.5 1.3 0 0 0</pose>
        <inertial>
          <mass>0.001</mass>
        </inertial>
        <collision name="sphere_collision">
          <geometry>
            <sphere>
              <radius>0.25</radius>
            </sphere>
          </geometry>
            <surface>
              <friction>
                <ode>
                  <mu>0.0</mu>
                  <mu2>0.0</mu2>
                </ode>
              </friction>
            </surface>
        </collision>
        <visual name="visual">
          <geometry>
            <sphere>
              <radius>0.25</radius>
            </sphere>
          </geometry>
        </visual>
       </link>

      <link name="spring_36">
        <pose>-1.5 -1 1.3 0 0 0</pose>
        <inertial>
          <mass>0.001</mass>
        </inertial>
        <collision name="sphere_collision">
          <geometry>
            <sphere>
              <radius>0.25</radius>
            </sphere>
          </geometry>
            <surface>
              <friction>
                <ode>
                  <mu>0.0</mu>
                  <mu2>0.0</mu2>
                </ode>
              </friction>
            </surface>
        </collision>
        <visual name="visual">
          <geometry>
            <sphere>
              <radius>0.25</radius>
            </sphere>
          </geometry>
        </visual>
       </link>

      <link name="spring_37">
        <pose>-1 -1 1.3 0 0 0</pose>
        <inertial>
          <mass>0.001</mass>
        </inertial>
        <collision name="sphere_collision">
          <geometry>
            <sphere>
              <radius>0.25</radius>
            </sphere>
          </geometry>
            <surface>
              <friction>
                <ode>
                  <mu>0.0</mu>
                  <mu2>0.0</mu2>
                </ode>
              </friction>
            </surface>
        </collision>
        <visual name="visual">
          <geometry>
            <sphere>
              <radius>0.25</radius>
            </sphere>
          </geometry>
        </visual>
       </link>

      <link name="spring_38">
        <pose>-0.5 -1 1.3 0 0 0</pose>
        <inertial>
          <mass>0.001</mass>
        </inertial>
        <collision name="sphere_collision">
          <geometry>
            <sphere>
              <radius>0.25</radius>
            </sphere>
          </geometry>
            <surface>
              <friction>
                <ode>
                  <mu>0.0</mu>
                  <mu2>0.0</mu2>
                </ode>
              </friction>
            </surface>
        </collision>
        <visual name="visual">
          <geometry>
            <sphere>
              <radius>0.25</radius>
            </sphere>
          </geometry>
        </visual>
       </link>

      <link name="spring_39">
        <pose>0 -1 1.3 0 0 0</pose>
        <inertial>
          <mass>0.001</mass>
        </inertial>
        <collision name="sphere_collision">
          <geometry>
            <sphere>
              <radius>0.25</radius>
            </sphere>
          </geometry>
            <surface>
              <friction>
                <ode>
                  <mu>0.0</mu>
                  <mu2>0.0</mu2>
                </ode>
              </friction>
            </surface>
        </collision>
        <visual name="visual">
          <geometry>
            <sphere>
              <radius>0.25</radius>
            </sphere>
          </geometry>
        </visual>
       </link>

      <link name="spring_40">
        <pose>0.5 -1 1.3 0 0 0</pose>
        <inertial>
          <mass>0.001</mass>
        </inertial>
        <collision name="sphere_collision">
          <geometry>
            <sphere>
              <radius>0.25</radius>
            </sphere>
          </geometry>
            <surface>
              <friction>
                <ode>
                  <mu>0.0</mu>
                  <mu2>0.0</mu2>
                </ode>
              </friction>
            </surface>
        </collision>
        <visual name="visual">
          <geometry>
            <sphere>
              <radius>0.25</radius>
            </sphere>
          </geometry>
        </visual>
       </link>

      <link name="spring_41">
        <pose>1 -1 1.3 0 0 0</pose>
        <inertial>
          <mass>0.001</mass>
        </inertial>
        <collision name="sphere_collision">
          <geometry>
            <sphere>
              <radius>0.25</radius>
            </sphere>
          </geometry>
            <surface>
              <friction>
                <ode>
                  <mu>0.0</mu>
                  <mu2>0.0</mu2>
                </ode>
              </friction>
            </surface>
        </collision>
        <visual name="visual">
          <geometry>
            <sphere>
              <radius>0.25</radius>
            </sphere>
          </geometry>
        </visual>
       </link>

      <link name="spring_42">
        <pose>1.5 -1 1.3 0 0 0</pose>
        <inertial>
          <mass>0.001</mass>
        </inertial>
        <collision name="sphere_collision">
          <geometry>
            <sphere>
              <radius>0.25</radius>
            </sphere>
          </geometry>
            <surface>
              <friction>
                <ode>
                  <mu>0.0</mu>
                  <mu2>0.0</mu2>
                </ode>
              </friction>
            </surface>
        </collision>
        <visual name="visual">
          <geometry>
            <sphere>
              <radius>0.25</radius>
            </sphere>
          </geometry>
        </visual>
       </link>

      <link name="spring_43">
        <pose>-1.5 -1.5 1.3 0 0 0</pose>
        <inertial>
          <mass>0.001</mass>
        </inertial>
        <collision name="sphere_collision">
          <geometry>
            <sphere>
              <radius>0.25</radius>
            </sphere>
          </geometry>
            <surface>
              <friction>
                <ode>
                  <mu>0.0</mu>
                  <mu2>0.0</mu2>
                </ode>
              </friction>
            </surface>
        </collision>
        <visual name="visual">
          <geometry>
            <sphere>
              <radius>0.25</radius>
            </sphere>
          </geometry>
        </visual>
       </link>

      <link name="spring_44">
        <pose>-1 -1.5 1.3 0 0 0</pose>
        <inertial>
          <mass>0.001</mass>
        </inertial>
        <collision name="sphere_collision">
          <geometry>
            <sphere>
              <radius>0.25</radius>
            </sphere>
          </geometry>
            <surface>
              <friction>
                <ode>
                  <mu>0.0</mu>
                  <mu2>0.0</mu2>
                </ode>
              </friction>
            </surface>
        </collision>
        <visual name="visual">
          <geometry>
            <sphere>
              <radius>0.25</radius>
            </sphere>
          </geometry>
        </visual>
       </link>

      <link name="spring_45">
        <pose>-0.5 -1.5 1.3 0 0 0</pose>
        <inertial>
          <mass>0.001</mass>
        </inertial>
        <collision name="sphere_collision">
          <geometry>
            <sphere>
              <radius>0.25</radius>
            </sphere>
          </geometry>
            <surface>
              <friction>
                <ode>
                  <mu>0.0</mu>
                  <mu2>0.0</mu2>
                </ode>
              </friction>
            </surface>
        </collision>
        <visual name="visual">
          <geometry>
            <sphere>
              <radius>0.25</radius>
            </sphere>
          </geometry>
        </visual>
       </link>

      <link name="spring_46">
        <pose>0 -1.5 1.3 0 0 0</pose>
        <inertial>
          <mass>0.001</mass>
        </inertial>
        <collision name="sphere_collision">
          <geometry>
            <sphere>
              <radius>0.25</radius>
            </sphere>
          </geometry>
            <surface>
              <friction>
                <ode>
                  <mu>0.0</mu>
                  <mu2>0.0</mu2>
                </ode>
              </friction>
            </surface>
        </collision>
        <visual name="visual">
          <geometry>
            <sphere>
              <radius>0.25</radius>
            </sphere>
          </geometry>
        </visual>
       </link>

      <link name="spring_47">
        <pose>0.5 -1.5 1.3 0 0 0</pose>
        <inertial>
          <mass>0.001</mass>
        </inertial>
        <collision name="sphere_collision">
          <geometry>
            <sphere>
              <radius>0.25</radius>
            </sphere>
          </geometry>
            <surface>
              <friction>
                <ode>
                  <mu>0.0</mu>
                  <mu2>0.0</mu2>
                </ode>
              </friction>
            </surface>
        </collision>
        <visual name="visual">
          <geometry>
            <sphere>
              <radius>0.25</radius>
            </sphere>
          </geometry>
        </visual>
       </link>

      <link name="spring_48">
        <pose>1 -1.5 1.3 0 0 0</pose>
        <inertial>
          <mass>0.001</mass>
        </inertial>
        <collision name="sphere_collision">
          <geometry>
            <sphere>
              <radius>0.25</radius>
            </sphere>
          </geometry>
            <surface>
              <friction>
                <ode>
                  <mu>0.0</mu>
                  <mu2>0.0</mu2>
                </ode>
              </friction>
            </surface>
        </collision>
        <visual name="visual">
          <geometry>
            <sphere>
              <radius>0.25</radius>
            </sphere>
          </geometry>
        </visual>
       </link>

      <link name="spring_49">
        <pose>1.5 -1.5 1.3 0 0 0</pose>
        <inertial>
          <mass>0.001</mass>
        </inertial>
        <collision name="sphere_collision">
          <geometry>
            <sphere>
              <radius>0.25</radius>
            </sphere>
          </geometry>
            <surface>
              <friction>
                <ode>
                  <mu>0.0</mu>
                  <mu2>0.0</mu2>
                </ode>
              </friction>
            </surface>
        </collision>
        <visual name="visual">
          <geometry>
            <sphere>
              <radius>0.25</radius>
            </sphere>
          </geometry>
        </visual>
       </link>

      <joint name = "joint_1" type="prismatic">
        <parent>plane</parent>
          <child>spring_1</child>
          <axis>
            <xyz>0 0 1</xyz>
          </axis>
      </joint>

     <joint name = "joint_2" type="prismatic">
        <parent>plane</parent>
          <child>spring_2</child>
          <axis>
            <xyz>0 0 1</xyz>
          </axis>
      </joint>

      <joint name = "joint_3" type="prismatic">
        <parent>plane</parent>
          <child>spring_3</child>
          <axis>
            <xyz>0 0 1</xyz>
          </axis>
      </joint>

      <joint name = "joint_4" type="prismatic">
        <parent>plane</parent>
          <child>spring_4</child>
          <axis>
            <xyz>0 0 1</xyz>
          </axis>
      </joint>

      <joint name = "joint_5" type="prismatic">
        <parent>plane</parent>
          <child>spring_5</child>
          <axis>
            <xyz>0 0 1</xyz>
          </axis>
      </joint>

      <joint name = "joint_6" type="prismatic">
        <parent>plane</parent>
          <child>spring_6</child>
          <axis>
            <xyz>0 0 1</xyz>
          </axis>
      </joint>

      <joint name = "joint_7" type="prismatic">
        <parent>plane</parent>
          <child>spring_7</child>
          <axis>
            <xyz>0 0 1</xyz>
          </axis>
      </joint>

      <joint name = "joint_8" type="prismatic">
        <parent>plane</parent>
          <child>spring_8</child>
          <axis>
            <xyz>0 0 1</xyz>
          </axis>
      </joint>

      <joint name = "joint_9" type="prismatic">
        <parent>plane</parent>
          <child>spring_9</child>
          <axis>
            <xyz>0 0 1</xyz>
          </axis>
      </joint>

     <joint name = "joint_10" type="prismatic">
        <parent>plane</parent>
          <child>spring_10</child>
          <axis>
            <xyz>0 0 1</xyz>
          </axis>
      </joint>

      <joint name = "joint_11" type="prismatic">
        <parent>plane</parent>
          <child>spring_11</child>
          <axis>
            <xyz>0 0 1</xyz>
          </axis>
      </joint>

      <joint name = "joint_12" type="prismatic">
        <parent>plane</parent>
          <child>spring_12</child>
          <axis>
            <xyz>0 0 1</xyz>
          </axis>
      </joint>

      <joint name = "joint_13" type="prismatic">
        <parent>plane</parent>
          <child>spring_13</child>
          <axis>
            <xyz>0 0 1</xyz>
          </axis>
      </joint>

      <joint name = "joint_14" type="prismatic">
        <parent>plane</parent>
          <child>spring_14</child>
          <axis>
            <xyz>0 0 1</xyz>
          </axis>
      </joint>

      <joint name = "joint_15" type="prismatic">
        <parent>plane</parent>
          <child>spring_15</child>
          <axis>
            <xyz>0 0 1</xyz>
          </axis>
      </joint>

      <joint name = "joint_16" type="prismatic">
        <parent>plane</parent>
          <child>spring_16</child>
          <axis>
            <xyz>0 0 1</xyz>
          </axis>
      </joint>

      <joint name = "joint_17" type="prismatic">
        <parent>plane</parent>
          <child>spring_17</child>
          <axis>
            <xyz>0 0 1</xyz>
          </axis>
      </joint>

      <joint name = "joint_18" type="prismatic">
        <parent>plane</parent>
          <child>spring_18</child>
          <axis>
            <xyz>0 0 1</xyz>
          </axis>
      </joint>

      <joint name = "joint_19" type="prismatic">
        <parent>plane</parent>
          <child>spring_19</child>
          <axis>
            <xyz>0 0 1</xyz>
          </axis>
      </joint>

      <joint name = "joint_20" type="prismatic">
        <parent>plane</parent>
          <child>spring_20</child>
          <axis>
            <xyz>0 0 1</xyz>
          </axis>
      </joint>

      <joint name = "joint_21" type="prismatic">
        <parent>plane</parent>
          <child>spring_21</child>
          <axis>
            <xyz>0 0 1</xyz>
          </axis>
      </joint>

      <joint name = "joint_22" type="prismatic">
        <parent>plane</parent>
          <child>spring_22</child>
          <axis>
            <xyz>0 0 1</xyz>
          </axis>
      </joint>

      <joint name = "joint_23" type="prismatic">
        <parent>plane</parent>
          <child>spring_23</child>
          <axis>
            <xyz>0 0 1</xyz>
          </axis>
      </joint>

      <joint name = "joint_24" type="prismatic">
        <parent>plane</parent>
          <child>spring_24</child>
          <axis>
            <xyz>0 0 1</xyz>
          </axis>
      </joint>

      <joint name = "joint_25" type="prismatic">
        <parent>plane</parent>
          <child>spring_25</child>
          <axis>
            <xyz>0 0 1</xyz>
          </axis>
      </joint>

      <joint name = "joint_26" type="prismatic">
        <parent>plane</parent>
          <child>spring_26</child>
          <axis>
            <xyz>0 0 1</xyz>
          </axis>
      </joint>

      <joint name = "joint_27" type="prismatic">
        <parent>plane</parent>
          <child>spring_27</child>
          <axis>
            <xyz>0 0 1</xyz>
          </axis>
      </joint>

      <joint name = "joint_28" type="prismatic">
        <parent>plane</parent>
          <child>spring_28</child>
          <axis>
            <xyz>0 0 1</xyz>
          </axis>
      </joint>

      <joint name = "joint_29" type="prismatic">
        <parent>plane</parent>
          <child>spring_29</child>
          <axis>
            <xyz>0 0 1</xyz>
          </axis>
      </joint>

      <joint name = "joint_30" type="prismatic">
        <parent>plane</parent>
          <child>spring_30</child>
          <axis>
            <xyz>0 0 1</xyz>
          </axis>
      </joint>

     <joint name = "joint_31" type="prismatic">
        <parent>plane</parent>
          <child>spring_31</child>
          <axis>
            <xyz>0 0 1</xyz>
          </axis>
      </joint>

      <joint name = "joint_32" type="prismatic">
        <parent>plane</parent>
          <child>spring_32</child>
          <axis>
            <xyz>0 0 1</xyz>
          </axis>
      </joint>

      <joint name = "joint_33" type="prismatic">
        <parent>plane</parent>
          <child>spring_33</child>
          <axis>
            <xyz>0 0 1</xyz>
          </axis>
      </joint>

       <joint name = "joint_34" type="prismatic">
        <parent>plane</parent>
          <child>spring_34</child>
          <axis>
            <xyz>0 0 1</xyz>
          </axis>
      </joint>

      <joint name = "joint_35" type="prismatic">
        <parent>plane</parent>
          <child>spring_35</child>
          <axis>
            <xyz>0 0 1</xyz>
          </axis>
      </joint>

       <joint name = "joint_36" type="prismatic">
        <parent>plane</parent>
          <child>spring_36</child>
          <axis>
            <xyz>0 0 1</xyz>
          </axis>
      </joint>

      <joint name = "joint_37" type="prismatic">
        <parent>plane</parent>
          <child>spring_37</child>
          <axis>
            <xyz>0 0 1</xyz>
          </axis>
      </joint>

      <joint name = "joint_38" type="prismatic">
        <parent>plane</parent>
          <child>spring_38</child>
          <axis>
            <xyz>0 0 1</xyz>
          </axis>
      </joint>

      <joint name = "joint_39" type="prismatic">
        <parent>plane</parent>
          <child>spring_39</child>
          <axis>
            <xyz>0 0 1</xyz>
          </axis>
      </joint>

      <joint name = "joint_40" type="prismatic">
        <parent>plane</parent>
          <child>spring_40</child>
          <axis>
            <xyz>0 0 1</xyz>
          </axis>
      </joint>

      <joint name = "joint_41" type="prismatic">
        <parent>plane</parent>
          <child>spring_41</child>
          <axis>
            <xyz>0 0 1</xyz>
          </axis>
      </joint>

      <joint name = "joint_42" type="prismatic">
        <parent>plane</parent>
          <child>spring_42</child>
          <axis>
            <xyz>0 0 1</xyz>
          </axis>
      </joint>

      <joint name = "joint_43" type="prismatic">
        <parent>plane</parent>
          <child>spring_43</child>
          <axis>
            <xyz>0 0 1</xyz>
          </axis>
      </joint>

      <joint name = "joint_44" type="prismatic">
        <parent>plane</parent>
          <child>spring_44</child>
          <axis>
            <xyz>0 0 1</xyz>
          </axis>
      </joint>

      <joint name = "joint_45" type="prismatic">
        <parent>plane</parent>
          <child>spring_45</child>
          <axis>
            <xyz>0 0 1</xyz>
          </axis>
      </joint>

      <joint name = "joint_46" type="prismatic">
        <parent>plane</parent>
          <child>spring_46</child>
          <axis>
            <xyz>0 0 1</xyz>
          </axis>
      </joint>

      <joint name = "joint_47" type="prismatic">
        <parent>plane</parent>
          <child>spring_47</child>
          <axis>
            <xyz>0 0 1</xyz>
          </axis>
      </joint>

      <joint name = "joint_48" type="prismatic">
        <parent>plane</parent>
          <child>spring_48</child>
          <axis>
            <xyz>0 0 1</xyz>
          </axis>
      </joint>

      <joint name = "joint_49" type="prismatic">
        <parent>plane</parent>
          <child>spring_49</child>
          <axis>
            <xyz>0 0 1</xyz>
          </axis>
      </joint>
      <plugin name="spring_joint" filename="libspring_joint.so" />

      <!--<joint name = "plane_joint" type="prismatic">
        <parent>world</parent>
          <child>plane</child>
          <axis>
            <xyz>0 0 1</xyz>
          </axis>
      </joint>
      <plugin name="plane_joint" filename="libplane_joint.so" />-->

    </model>
</sdf>
