<sdf version='1.4'>
  <model name='spring_array'>
    <pose>0 0 0 0 -0 0</pose>
    <link name='plane'>
      <pose>0 0 0.02 0 -0 0</pose>
      <inertial>
        <mass>20</mass>
      </inertial>
      <collision name='collision'>
        <geometry>
          <box>
            <size>0.01125 0.01125 0.00025</size>
          </box>
        </geometry>
        <surface>
          <friction>
            <ode>
              <mu>0</mu>
              <mu2>0</mu2>
            </ode>
          </friction>
        </surface>
      </collision>
      <visual name='visual'>
        <geometry>
          <box>
            <size>0.01125 0.01125 0.00025</size>
          </box>
        </geometry>
        <material>
          <ambient>1 1 1 1</ambient>
          <diffuse>1 1 1 1</diffuse>
          <specular>0.1 0.1 0.1 1</specular>
          <emissive>0 0 0 0</emissive>
        </material>
      </visual>
      <velocity_decay>
        <linear>0</linear>
        <angular>0</angular>
      </velocity_decay>
    </link>
    <joint name='plane_joint' type='prismatic'>
      <parent>world</parent>
      <child>plane</child>
      <axis>
        <xyz>0 0 1</xyz>
        <limit>
          <lower>1e+16</lower>
          <upper>-1e+16</upper>
        </limit>
      </axis>
    </joint>
    <link name='spring_1'>
      <pose>-0.0025 0.0025 0.04 0 -0 0</pose>
      <inertial>
        <mass>0.00235</mass>
      </inertial>
      <collision name='sphere_collision'>
        <geometry>
          <sphere>
            <radius>0.00125</radius>
          </sphere>
        </geometry>
        <surface>
          <friction>
            <ode>
              <mu>0</mu>
              <mu2>0</mu2>
            </ode>
          </friction>
        </surface>
      </collision>
      <visual name='visual'>
        <geometry>
          <sphere>
            <radius>0.00125</radius>
          </sphere>
        </geometry>
        <material>
          <ambient>1 0 0 1</ambient>
          <diffuse>1 0 0 1</diffuse>
          <specular>0.1 0.1 0.1 1</specular>
          <emissive>0 0 0 0</emissive>
        </material>
      </visual>
      <velocity_decay>
        <linear>0</linear>
        <angular>0</angular>
      </velocity_decay>
    </link>
    <joint name='spring_joint_1' type='prismatic'>
      <parent>plane</parent>
      <child>spring_1</child>
      <axis>
        <xyz>0 0 1</xyz>
        <limit>
          <lower>-1e+16</lower>
          <upper>1e+16</upper>
        </limit>
      </axis>
    </joint>
    <link name='spring_2'>
      <pose>4.33681e-19 0.0025 0.04 0 -0 0</pose>
      <inertial>
        <mass>0.00235</mass>
      </inertial>
      <collision name='sphere_collision'>
        <geometry>
          <sphere>
            <radius>0.00125</radius>
          </sphere>
        </geometry>
        <surface>
          <friction>
            <ode>
              <mu>0</mu>
              <mu2>0</mu2>
            </ode>
          </friction>
        </surface>
      </collision>
      <visual name='visual'>
        <geometry>
          <sphere>
            <radius>0.00125</radius>
          </sphere>
        </geometry>
        <material>
          <ambient>1 0 0 1</ambient>
          <diffuse>1 0 0 1</diffuse>
          <specular>0.1 0.1 0.1 1</specular>
          <emissive>0 0 0 0</emissive>
        </material>
      </visual>
      <velocity_decay>
        <linear>0</linear>
        <angular>0</angular>
      </velocity_decay>
    </link>
    <joint name='spring_joint_2' type='prismatic'>
      <parent>plane</parent>
      <child>spring_2</child>
      <axis>
        <xyz>0 0 1</xyz>
        <limit>
          <lower>-1e+16</lower>
          <upper>1e+16</upper>
        </limit>
      </axis>
    </joint>
    <link name='spring_3'>
      <pose>0.0025 0.0025 0.04 0 -0 0</pose>
      <inertial>
        <mass>0.00235</mass>
      </inertial>
      <collision name='sphere_collision'>
        <geometry>
          <sphere>
            <radius>0.00125</radius>
          </sphere>
        </geometry>
        <surface>
          <friction>
            <ode>
              <mu>0</mu>
              <mu2>0</mu2>
            </ode>
          </friction>
        </surface>
      </collision>
      <visual name='visual'>
        <geometry>
          <sphere>
            <radius>0.00125</radius>
          </sphere>
        </geometry>
        <material>
          <ambient>1 0 0 1</ambient>
          <diffuse>1 0 0 1</diffuse>
          <specular>0.1 0.1 0.1 1</specular>
          <emissive>0 0 0 0</emissive>
        </material>
      </visual>
      <velocity_decay>
        <linear>0</linear>
        <angular>0</angular>
      </velocity_decay>
    </link>
    <joint name='spring_joint_3' type='prismatic'>
      <parent>plane</parent>
      <child>spring_3</child>
      <axis>
        <xyz>0 0 1</xyz>
        <limit>
          <lower>-1e+16</lower>
          <upper>1e+16</upper>
        </limit>
      </axis>
    </joint>
    <link name='spring_4'>
      <pose>-0.0025 -4.33681e-19 0.04 0 -0 0</pose>
      <inertial>
        <mass>0.00235</mass>
      </inertial>
      <collision name='sphere_collision'>
        <geometry>
          <sphere>
            <radius>0.00125</radius>
          </sphere>
        </geometry>
        <surface>
          <friction>
            <ode>
              <mu>0</mu>
              <mu2>0</mu2>
            </ode>
          </friction>
        </surface>
      </collision>
      <visual name='visual'>
        <geometry>
          <sphere>
            <radius>0.00125</radius>
          </sphere>
        </geometry>
        <material>
          <ambient>1 0 0 1</ambient>
          <diffuse>1 0 0 1</diffuse>
          <specular>0.1 0.1 0.1 1</specular>
          <emissive>0 0 0 0</emissive>
        </material>
      </visual>
      <velocity_decay>
        <linear>0</linear>
        <angular>0</angular>
      </velocity_decay>
    </link>
    <joint name='spring_joint_4' type='prismatic'>
      <parent>plane</parent>
      <child>spring_4</child>
      <axis>
        <xyz>0 0 1</xyz>
        <limit>
          <lower>-1e+16</lower>
          <upper>1e+16</upper>
        </limit>
      </axis>
    </joint>
    <link name='spring_5'>
      <pose>4.33681e-19 -4.33681e-19 0.04 0 -0 0</pose>
      <inertial>
        <mass>0.00235</mass>
      </inertial>
      <collision name='sphere_collision'>
        <geometry>
          <sphere>
            <radius>0.00125</radius>
          </sphere>
        </geometry>
        <surface>
          <friction>
            <ode>
              <mu>0</mu>
              <mu2>0</mu2>
            </ode>
          </friction>
        </surface>
      </collision>
      <visual name='visual'>
        <geometry>
          <sphere>
            <radius>0.00125</radius>
          </sphere>
        </geometry>
        <material>
          <ambient>1 0 0 1</ambient>
          <diffuse>1 0 0 1</diffuse>
          <specular>0.1 0.1 0.1 1</specular>
          <emissive>0 0 0 0</emissive>
        </material>
      </visual>
      <velocity_decay>
        <linear>0</linear>
        <angular>0</angular>
      </velocity_decay>
    </link>
    <joint name='spring_joint_5' type='prismatic'>
      <parent>plane</parent>
      <child>spring_5</child>
      <axis>
        <xyz>0 0 1</xyz>
        <limit>
          <lower>-1e+16</lower>
          <upper>1e+16</upper>
        </limit>
      </axis>
    </joint>
    <link name='spring_6'>
      <pose>0.0025 -4.33681e-19 0.04 0 -0 0</pose>
      <inertial>
        <mass>0.00235</mass>
      </inertial>
      <collision name='sphere_collision'>
        <geometry>
          <sphere>
            <radius>0.00125</radius>
          </sphere>
        </geometry>
        <surface>
          <friction>
            <ode>
              <mu>0</mu>
              <mu2>0</mu2>
            </ode>
          </friction>
        </surface>
      </collision>
      <visual name='visual'>
        <geometry>
          <sphere>
            <radius>0.00125</radius>
          </sphere>
        </geometry>
        <material>
          <ambient>1 0 0 1</ambient>
          <diffuse>1 0 0 1</diffuse>
          <specular>0.1 0.1 0.1 1</specular>
          <emissive>0 0 0 0</emissive>
        </material>
      </visual>
      <velocity_decay>
        <linear>0</linear>
        <angular>0</angular>
      </velocity_decay>
    </link>
    <joint name='spring_joint_6' type='prismatic'>
      <parent>plane</parent>
      <child>spring_6</child>
      <axis>
        <xyz>0 0 1</xyz>
        <limit>
          <lower>-1e+16</lower>
          <upper>1e+16</upper>
        </limit>
      </axis>
    </joint>
    <link name='spring_7'>
      <pose>-0.0025 -0.0025 0.04 0 -0 0</pose>
      <inertial>
        <mass>0.00235</mass>
      </inertial>
      <collision name='sphere_collision'>
        <geometry>
          <sphere>
            <radius>0.00125</radius>
          </sphere>
        </geometry>
        <surface>
          <friction>
            <ode>
              <mu>0</mu>
              <mu2>0</mu2>
            </ode>
          </friction>
        </surface>
      </collision>
      <visual name='visual'>
        <geometry>
          <sphere>
            <radius>0.00125</radius>
          </sphere>
        </geometry>
        <material>
          <ambient>1 0 0 1</ambient>
          <diffuse>1 0 0 1</diffuse>
          <specular>0.1 0.1 0.1 1</specular>
          <emissive>0 0 0 0</emissive>
        </material>
      </visual>
      <velocity_decay>
        <linear>0</linear>
        <angular>0</angular>
      </velocity_decay>
    </link>
    <joint name='spring_joint_7' type='prismatic'>
      <parent>plane</parent>
      <child>spring_7</child>
      <axis>
        <xyz>0 0 1</xyz>
        <limit>
          <lower>-1e+16</lower>
          <upper>1e+16</upper>
        </limit>
      </axis>
    </joint>
    <link name='spring_8'>
      <pose>4.33681e-19 -0.0025 0.04 0 -0 0</pose>
      <inertial>
        <mass>0.00235</mass>
      </inertial>
      <collision name='sphere_collision'>
        <geometry>
          <sphere>
            <radius>0.00125</radius>
          </sphere>
        </geometry>
        <surface>
          <friction>
            <ode>
              <mu>0</mu>
              <mu2>0</mu2>
            </ode>
          </friction>
        </surface>
      </collision>
      <visual name='visual'>
        <geometry>
          <sphere>
            <radius>0.00125</radius>
          </sphere>
        </geometry>
        <material>
          <ambient>1 0 0 1</ambient>
          <diffuse>1 0 0 1</diffuse>
          <specular>0.1 0.1 0.1 1</specular>
          <emissive>0 0 0 0</emissive>
        </material>
      </visual>
      <velocity_decay>
        <linear>0</linear>
        <angular>0</angular>
      </velocity_decay>
    </link>
    <joint name='spring_joint_8' type='prismatic'>
      <parent>plane</parent>
      <child>spring_8</child>
      <axis>
        <xyz>0 0 1</xyz>
        <limit>
          <lower>-1e+16</lower>
          <upper>1e+16</upper>
        </limit>
      </axis>
    </joint>
    <link name='spring_9'>
      <pose>0.0025 -0.0025 0.04 0 -0 0</pose>
      <inertial>
        <mass>0.00235</mass>
      </inertial>
      <collision name='sphere_collision'>
        <geometry>
          <sphere>
            <radius>0.00125</radius>
          </sphere>
        </geometry>
        <surface>
          <friction>
            <ode>
              <mu>0</mu>
              <mu2>0</mu2>
            </ode>
          </friction>
        </surface>
      </collision>
      <visual name='visual'>
        <geometry>
          <sphere>
            <radius>0.00125</radius>
          </sphere>
        </geometry>
        <material>
          <ambient>1 0 0 1</ambient>
          <diffuse>1 0 0 1</diffuse>
          <specular>0.1 0.1 0.1 1</specular>
          <emissive>0 0 0 0</emissive>
        </material>
      </visual>
      <velocity_decay>
        <linear>0</linear>
        <angular>0</angular>
      </velocity_decay>
    </link>
    <joint name='spring_joint_9' type='prismatic'>
      <parent>plane</parent>
      <child>spring_9</child>
      <axis>
        <xyz>0 0 1</xyz>
        <limit>
          <lower>-1e+16</lower>
          <upper>1e+16</upper>
        </limit>
      </axis>
    </joint>
    <plugin name='skin_tactile_joint' filename='libTactileSensorPlugin.so'/>
    <plugin name='skin_tactile_joint' filename='libSkinJointPlugin.so'/>
    <plugin name='plane_joint' filename='libplane_joint.so'/>
  </model>
</sdf>
