<?xml version="1.0" ?>
<sdf version='1.4'>
    <model name='cylinder'>
		<link name='cylinder_link'>
	      <pose>0 0 0.5 0 0 0</pose>
	      <inertial>
              <mass>10</mass>
        	  <inertia>
		          <ixx>0.145833</ixx>
		          <ixy>0</ixy>
		          <ixz>0</ixz>
		          <iyy>0.145833</iyy>
		          <iyz>0</iyz>
		          <izz>0</izz>
	          </inertia>
	      </inertial>
	      <collision name='collision_cylinder'>
	          <pose>0 0 0 0 0 0</pose>
	          <geometry>
	              <cylinder>
	              	  <radius>0.5</radius>
	              	  <length>1</length>
	              </cylinder>
	          </geometry>
	      </collision>
	      <visual name='visual'>
	          <pose>0 0 0 0 0 0</pose>
	          <geometry>
	              <cylinder>
	                  <radius>0.5</radius>
	                  <length>1</length>
	              </cylinder>
    		  </geometry>
	      </visual>
	      <velocity_decay>
	          <linear>0</linear>
	          <angular>0</angular>
	      </velocity_decay>
	      
	      	<sensor name='my_contact' type='contact'>
	      		<plugin name="VisualizeContactPlugin" filename="libVisualizeContactPlugin.so"/>
          		<contact>
            		<collision>collision_cylinder</collision>
          		</contact>
          		<update_rate> 5 </update_rate>
		</sensor>
	    </link>
	    
		<joint name = "my_mass_joint" type="prismatic">
        	<parent>world</parent>
          	<child>cylinder_link</child>
	        <axis>
            	<xyz>0 0 1</xyz>
          	</axis>
      	</joint>
	      
      	<plugin name="mass_joint" filename="libMassJoint.so" />
      	<plugin name='cylinderJointControl' filename='libCylinderTrajectoryPlugin.so'>
      		<file_name>cylinder</file_name>
   	  	</plugin>
    
    </model>
</sdf>

