<sdf version='1.4'>
  <model name='hinge'>
    <link name='base_link'>
      <pose>0 0 0 0 -0 0</pose>
      <inertial>
        <pose>0.0018612 0.0028669 0.0027918 0 -0 0</pose>
        <mass>0.13081</mass>
        <inertia>
          <ixx>3.5032e-05</ixx>
          <ixy>-4.1704e-08</ixy>
          <ixz>4.377e-09</ixz>
          <iyy>0.00011772</iyy>
          <iyz>-2.0137e-06</iyz>
          <izz>0.00015165</izz>
        </inertia>
      </inertial>
      <collision name='base_link_collision'>
        <pose>0 0 0 0 -0 0</pose>
        <geometry>
          <mesh>
            <scale>10 10 10</scale>
            <uri>model://hinge/meshes/base_link.dae</uri>
          </mesh>
        </geometry>
      </collision>
      <visual name='base_link_visual'>
        <pose>0 0 0 0 -0 0</pose>
        <geometry>
          <mesh>
            <scale>10 10 10</scale>
            <uri>model://hinge/meshes/base_link.dae</uri>
          </mesh>
        </geometry>
      </visual>
      <velocity_decay>
        <linear>0</linear>
        <angular>0</angular>
      </velocity_decay>
    </link>
    <link name='link_1'>
      <pose>0 0 0.234256 0.32455 -6.8094e-16 -3.14159</pose>
      <inertial>
        <pose>-0.0018882 -0.023112 0.0029924 0 -0 0</pose>
        <mass>0.12092</mass>
        <inertia>
          <ixx>3.0054e-05</ixx>
          <ixy>-2.3603e-08</ixy>
          <ixz>1.0075e-09</ixz>
          <iyy>9.3473e-05</iyy>
          <iyz>-1.4491e-06</iyz>
          <izz>0.00012271</izz>
        </inertia>
      </inertial>
      <collision name='link_1_collision'>
        <pose>0 0 0 0 -0 0</pose>
        <geometry>
          <mesh>
            <scale>10 10 10</scale>
            <uri>model://hinge/meshes/link_1.dae</uri>
          </mesh>
        </geometry>
      </collision>
      <visual name='link_1_visual'>
        <pose>0 0 0 0 -0 0</pose>
        <geometry>
          <mesh>
            <scale>10 10 10</scale>
            <uri>model://hinge/meshes/link_1.dae</uri>
          </mesh>
        </geometry>
      </visual>
      <velocity_decay>
        <linear>0</linear>
        <angular>0</angular>
      </velocity_decay>
    </link>
    <joint name='joint_1' type='revolute'>
      <child>link_1</child>
      <parent>base_link</parent>
      <axis>
        <xyz>-1 0 0</xyz>
        <limit>
          <lower>-1.2462</lower>
          <upper>1.2462</upper>
          <effort>0</effort>
          <velocity>0</velocity>
        </limit>
        <dynamics/>
      </axis>
    </joint>
     <joint name = "my_mass_joint" type="prismatic">
        <parent>world</parent>
          <child>base_link</child>
          <axis>
            <xyz>0 0 1</xyz>
          </axis>
      </joint>
      <plugin name="mass_joint" filename="libmass_joint.so" />
  </model>
</sdf>
